[2022-11-28T08:55:04.898+0000] {taskinstance.py:1165} INFO - Dependencies all met for <TaskInstance: dag_youtube_api.creatableLoad manual__2022-11-28T08:49:52.733978+00:00 [queued]>
[2022-11-28T08:55:04.932+0000] {taskinstance.py:1165} INFO - Dependencies all met for <TaskInstance: dag_youtube_api.creatableLoad manual__2022-11-28T08:49:52.733978+00:00 [queued]>
[2022-11-28T08:55:04.933+0000] {taskinstance.py:1362} INFO - 
--------------------------------------------------------------------------------
[2022-11-28T08:55:04.933+0000] {taskinstance.py:1363} INFO - Starting attempt 1 of 2
[2022-11-28T08:55:04.934+0000] {taskinstance.py:1364} INFO - 
--------------------------------------------------------------------------------
[2022-11-28T08:55:04.966+0000] {taskinstance.py:1383} INFO - Executing <Task(PythonOperator): creatableLoad> on 2022-11-28 08:49:52.733978+00:00
[2022-11-28T08:55:04.997+0000] {standard_task_runner.py:55} INFO - Started process 1328 to run task
[2022-11-28T08:55:05.009+0000] {standard_task_runner.py:82} INFO - Running: ['***', 'tasks', 'run', 'dag_youtube_api', 'creatableLoad', 'manual__2022-11-28T08:49:52.733978+00:00', '--job-id', '521', '--raw', '--subdir', 'DAGS_FOLDER/dag_youtube_api.py', '--cfg-path', '/tmp/tmpvng5i0nc']
[2022-11-28T08:55:05.014+0000] {standard_task_runner.py:83} INFO - Job 521: Subtask creatableLoad
[2022-11-28T08:55:05.156+0000] {task_command.py:376} INFO - Running <TaskInstance: dag_youtube_api.creatableLoad manual__2022-11-28T08:49:52.733978+00:00 [running]> on host 8af950e53524
[2022-11-28T08:55:05.347+0000] {taskinstance.py:1592} INFO - Exporting the following env vars:
AIRFLOW_CTX_DAG_OWNER=***
AIRFLOW_CTX_DAG_ID=dag_youtube_api
AIRFLOW_CTX_TASK_ID=creatableLoad
AIRFLOW_CTX_EXECUTION_DATE=2022-11-28T08:49:52.733978+00:00
AIRFLOW_CTX_TRY_NUMBER=1
AIRFLOW_CTX_DAG_RUN_ID=manual__2022-11-28T08:49:52.733978+00:00
[2022-11-28T08:55:05.361+0000] {taskinstance.py:1851} ERROR - Task failed with exception
Traceback (most recent call last):
  File "/home/airflow/.local/lib/python3.7/site-packages/airflow/operators/python.py", line 175, in execute
    return_value = self.execute_callable()
  File "/home/airflow/.local/lib/python3.7/site-packages/airflow/operators/python.py", line 193, in execute_callable
    return self.python_callable(*self.op_args, **self.op_kwargs)
  File "/opt/airflow/dags/dag_youtube_api.py", line 183, in creatableLoad
    """
psycopg2.errors.UndefinedTable: relation "youtube_id" does not exist

[2022-11-28T08:55:05.422+0000] {taskinstance.py:1406} INFO - Marking task as UP_FOR_RETRY. dag_id=dag_youtube_api, task_id=creatableLoad, execution_date=20221128T084952, start_date=20221128T085504, end_date=20221128T085505
[2022-11-28T08:55:05.504+0000] {standard_task_runner.py:105} ERROR - Failed to execute job 521 for task creatableLoad (relation "youtube_id" does not exist
; 1328)
[2022-11-28T08:55:05.564+0000] {local_task_job.py:159} INFO - Task exited with return code 1
[2022-11-28T08:55:05.679+0000] {taskinstance.py:2623} INFO - 0 downstream tasks scheduled from follow-on schedule check
