[2022-11-27T12:38:42.126+0000] {taskinstance.py:1165} INFO - Dependencies all met for <TaskInstance: using_pandas_demo.creatableLoad manual__2022-11-27T12:33:32.562953+00:00 [queued]>
[2022-11-27T12:38:42.137+0000] {taskinstance.py:1165} INFO - Dependencies all met for <TaskInstance: using_pandas_demo.creatableLoad manual__2022-11-27T12:33:32.562953+00:00 [queued]>
[2022-11-27T12:38:42.137+0000] {taskinstance.py:1362} INFO - 
--------------------------------------------------------------------------------
[2022-11-27T12:38:42.137+0000] {taskinstance.py:1363} INFO - Starting attempt 2 of 2
[2022-11-27T12:38:42.137+0000] {taskinstance.py:1364} INFO - 
--------------------------------------------------------------------------------
[2022-11-27T12:38:42.150+0000] {taskinstance.py:1383} INFO - Executing <Task(PythonOperator): creatableLoad> on 2022-11-27 12:33:32.562953+00:00
[2022-11-27T12:38:42.156+0000] {standard_task_runner.py:55} INFO - Started process 1073 to run task
[2022-11-27T12:38:42.160+0000] {standard_task_runner.py:82} INFO - Running: ['***', 'tasks', 'run', 'using_pandas_demo', 'creatableLoad', 'manual__2022-11-27T12:33:32.562953+00:00', '--job-id', '349', '--raw', '--subdir', 'DAGS_FOLDER/dag_pandas_demo.py', '--cfg-path', '/tmp/tmpvh66ls1m']
[2022-11-27T12:38:42.162+0000] {standard_task_runner.py:83} INFO - Job 349: Subtask creatableLoad
[2022-11-27T12:38:42.223+0000] {task_command.py:376} INFO - Running <TaskInstance: using_pandas_demo.creatableLoad manual__2022-11-27T12:33:32.562953+00:00 [running]> on host 1977dd9b5152
[2022-11-27T12:38:42.288+0000] {taskinstance.py:1592} INFO - Exporting the following env vars:
AIRFLOW_CTX_DAG_OWNER=***
AIRFLOW_CTX_DAG_ID=using_pandas_demo
AIRFLOW_CTX_TASK_ID=creatableLoad
AIRFLOW_CTX_EXECUTION_DATE=2022-11-27T12:33:32.562953+00:00
AIRFLOW_CTX_TRY_NUMBER=2
AIRFLOW_CTX_DAG_RUN_ID=manual__2022-11-27T12:33:32.562953+00:00
[2022-11-27T12:38:42.289+0000] {logging_mixin.py:137} INFO - connection to server at "localhost" (127.0.0.1), port 5432 failed: Connection refused
	Is the server running on that host and accepting TCP/IP connections?
connection to server at "localhost" (::1), port 5432 failed: Cannot assign requested address
	Is the server running on that host and accepting TCP/IP connections?
[2022-11-27T12:38:42.290+0000] {taskinstance.py:1851} ERROR - Task failed with exception
Traceback (most recent call last):
  File "/home/airflow/.local/lib/python3.7/site-packages/airflow/operators/python.py", line 175, in execute
    return_value = self.execute_callable()
  File "/home/airflow/.local/lib/python3.7/site-packages/airflow/operators/python.py", line 193, in execute_callable
    return self.python_callable(*self.op_args, **self.op_kwargs)
  File "/opt/airflow/dags/dag_pandas_demo.py", line 49, in creatableLoad
    cursor = dbconnect.cursor()
UnboundLocalError: local variable 'dbconnect' referenced before assignment
[2022-11-27T12:38:42.298+0000] {taskinstance.py:1406} INFO - Marking task as FAILED. dag_id=using_pandas_demo, task_id=creatableLoad, execution_date=20221127T123332, start_date=20221127T123842, end_date=20221127T123842
[2022-11-27T12:38:42.309+0000] {standard_task_runner.py:105} ERROR - Failed to execute job 349 for task creatableLoad (local variable 'dbconnect' referenced before assignment; 1073)
[2022-11-27T12:38:42.331+0000] {local_task_job.py:159} INFO - Task exited with return code 1
[2022-11-27T12:38:42.347+0000] {taskinstance.py:2623} INFO - 0 downstream tasks scheduled from follow-on schedule check
