[2022-11-28T16:30:17.650+0000] {taskinstance.py:1165} INFO - Dependencies all met for <TaskInstance: dag_try_oop.loadYtApiOperator scheduled__2022-11-27T21:30:00+00:00 [queued]>
[2022-11-28T16:30:17.874+0000] {taskinstance.py:1165} INFO - Dependencies all met for <TaskInstance: dag_try_oop.loadYtApiOperator scheduled__2022-11-27T21:30:00+00:00 [queued]>
[2022-11-28T16:30:17.876+0000] {taskinstance.py:1362} INFO - 
--------------------------------------------------------------------------------
[2022-11-28T16:30:17.878+0000] {taskinstance.py:1363} INFO - Starting attempt 2 of 2
[2022-11-28T16:30:17.880+0000] {taskinstance.py:1364} INFO - 
--------------------------------------------------------------------------------
[2022-11-28T16:30:18.290+0000] {taskinstance.py:1383} INFO - Executing <Task(loadYtApiOperator): loadYtApiOperator> on 2022-11-27 21:30:00+00:00
[2022-11-28T16:30:18.353+0000] {standard_task_runner.py:55} INFO - Started process 639 to run task
[2022-11-28T16:30:18.500+0000] {standard_task_runner.py:82} INFO - Running: ['***', 'tasks', 'run', 'dag_try_oop', 'loadYtApiOperator', 'scheduled__2022-11-27T21:30:00+00:00', '--job-id', '821', '--raw', '--subdir', 'DAGS_FOLDER/dag_try_oop.py', '--cfg-path', '/tmp/tmpfpp3mfs7']
[2022-11-28T16:30:18.561+0000] {standard_task_runner.py:83} INFO - Job 821: Subtask loadYtApiOperator
[2022-11-28T16:30:20.174+0000] {task_command.py:376} INFO - Running <TaskInstance: dag_try_oop.loadYtApiOperator scheduled__2022-11-27T21:30:00+00:00 [running]> on host 1dd759b3e30c
[2022-11-28T16:30:21.869+0000] {taskinstance.py:1592} INFO - Exporting the following env vars:
AIRFLOW_CTX_DAG_OWNER=***
AIRFLOW_CTX_DAG_ID=dag_try_oop
AIRFLOW_CTX_TASK_ID=loadYtApiOperator
AIRFLOW_CTX_EXECUTION_DATE=2022-11-27T21:30:00+00:00
AIRFLOW_CTX_TRY_NUMBER=2
AIRFLOW_CTX_DAG_RUN_ID=scheduled__2022-11-27T21:30:00+00:00
[2022-11-28T16:30:21.994+0000] {taskinstance.py:1851} ERROR - Task failed with exception
Traceback (most recent call last):
  File "/opt/airflow/plugins/operators/loadYtApiOperator.py", line 70, in execute
    row.split(",")[11])
IndexError: list index out of range
[2022-11-28T16:30:22.237+0000] {taskinstance.py:1406} INFO - Marking task as FAILED. dag_id=dag_try_oop, task_id=loadYtApiOperator, execution_date=20221127T213000, start_date=20221128T163017, end_date=20221128T163022
[2022-11-28T16:30:22.586+0000] {standard_task_runner.py:105} ERROR - Failed to execute job 821 for task loadYtApiOperator (list index out of range; 639)
[2022-11-28T16:30:22.683+0000] {local_task_job.py:159} INFO - Task exited with return code 1
[2022-11-28T16:30:22.905+0000] {taskinstance.py:2623} INFO - 0 downstream tasks scheduled from follow-on schedule check
