[2022-11-27T12:35:19.543+0000] {taskinstance.py:1165} INFO - Dependencies all met for <TaskInstance: using_pandas_demo.creatableLoad manual__2022-11-27T12:30:09.313451+00:00 [queued]>
[2022-11-27T12:35:19.553+0000] {taskinstance.py:1165} INFO - Dependencies all met for <TaskInstance: using_pandas_demo.creatableLoad manual__2022-11-27T12:30:09.313451+00:00 [queued]>
[2022-11-27T12:35:19.553+0000] {taskinstance.py:1362} INFO - 
--------------------------------------------------------------------------------
[2022-11-27T12:35:19.553+0000] {taskinstance.py:1363} INFO - Starting attempt 2 of 2
[2022-11-27T12:35:19.553+0000] {taskinstance.py:1364} INFO - 
--------------------------------------------------------------------------------
[2022-11-27T12:35:19.599+0000] {taskinstance.py:1383} INFO - Executing <Task(PythonOperator): creatableLoad> on 2022-11-27 12:30:09.313451+00:00
[2022-11-27T12:35:19.604+0000] {standard_task_runner.py:55} INFO - Started process 907 to run task
[2022-11-27T12:35:19.608+0000] {standard_task_runner.py:82} INFO - Running: ['***', 'tasks', 'run', 'using_pandas_demo', 'creatableLoad', 'manual__2022-11-27T12:30:09.313451+00:00', '--job-id', '348', '--raw', '--subdir', 'DAGS_FOLDER/dag_pandas_demo.py', '--cfg-path', '/tmp/tmpcmokpz6k']
[2022-11-27T12:35:19.610+0000] {standard_task_runner.py:83} INFO - Job 348: Subtask creatableLoad
[2022-11-27T12:35:19.703+0000] {task_command.py:376} INFO - Running <TaskInstance: using_pandas_demo.creatableLoad manual__2022-11-27T12:30:09.313451+00:00 [running]> on host 1977dd9b5152
[2022-11-27T12:35:19.887+0000] {taskinstance.py:1592} INFO - Exporting the following env vars:
AIRFLOW_CTX_DAG_OWNER=***
AIRFLOW_CTX_DAG_ID=using_pandas_demo
AIRFLOW_CTX_TASK_ID=creatableLoad
AIRFLOW_CTX_EXECUTION_DATE=2022-11-27T12:30:09.313451+00:00
AIRFLOW_CTX_TRY_NUMBER=2
AIRFLOW_CTX_DAG_RUN_ID=manual__2022-11-27T12:30:09.313451+00:00
[2022-11-27T12:35:19.888+0000] {logging_mixin.py:137} INFO - connection to server at "localhost" (127.0.0.1), port 5432 failed: Connection refused
	Is the server running on that host and accepting TCP/IP connections?
connection to server at "localhost" (::1), port 5432 failed: Cannot assign requested address
	Is the server running on that host and accepting TCP/IP connections?
[2022-11-27T12:35:19.889+0000] {taskinstance.py:1851} ERROR - Task failed with exception
Traceback (most recent call last):
  File "/home/airflow/.local/lib/python3.7/site-packages/airflow/operators/python.py", line 175, in execute
    return_value = self.execute_callable()
  File "/home/airflow/.local/lib/python3.7/site-packages/airflow/operators/python.py", line 193, in execute_callable
    return self.python_callable(*self.op_args, **self.op_kwargs)
  File "/opt/airflow/dags/dag_pandas_demo.py", line 49, in creatableLoad
    cursor = dbconnect.cursor()
UnboundLocalError: local variable 'dbconnect' referenced before assignment
[2022-11-27T12:35:19.896+0000] {taskinstance.py:1406} INFO - Marking task as FAILED. dag_id=using_pandas_demo, task_id=creatableLoad, execution_date=20221127T123009, start_date=20221127T123519, end_date=20221127T123519
[2022-11-27T12:35:19.943+0000] {standard_task_runner.py:105} ERROR - Failed to execute job 348 for task creatableLoad (local variable 'dbconnect' referenced before assignment; 907)
[2022-11-27T12:35:19.980+0000] {local_task_job.py:159} INFO - Task exited with return code 1
[2022-11-27T12:35:19.995+0000] {taskinstance.py:2623} INFO - 0 downstream tasks scheduled from follow-on schedule check
