[2022-11-28T16:38:38.924+0000] {taskinstance.py:1165} INFO - Dependencies all met for <TaskInstance: dag_try_oop.extractYtApiOperator scheduled__2022-11-28T13:00:00+00:00 [queued]>
[2022-11-28T16:38:38.971+0000] {taskinstance.py:1165} INFO - Dependencies all met for <TaskInstance: dag_try_oop.extractYtApiOperator scheduled__2022-11-28T13:00:00+00:00 [queued]>
[2022-11-28T16:38:38.973+0000] {taskinstance.py:1362} INFO - 
--------------------------------------------------------------------------------
[2022-11-28T16:38:38.975+0000] {taskinstance.py:1363} INFO - Starting attempt 1 of 2
[2022-11-28T16:38:38.976+0000] {taskinstance.py:1364} INFO - 
--------------------------------------------------------------------------------
[2022-11-28T16:38:39.102+0000] {taskinstance.py:1383} INFO - Executing <Task(extractYtApiOperator): extractYtApiOperator> on 2022-11-28 13:00:00+00:00
[2022-11-28T16:38:39.126+0000] {standard_task_runner.py:55} INFO - Started process 1391 to run task
[2022-11-28T16:38:39.144+0000] {standard_task_runner.py:82} INFO - Running: ['***', 'tasks', 'run', 'dag_try_oop', 'extractYtApiOperator', 'scheduled__2022-11-28T13:00:00+00:00', '--job-id', '992', '--raw', '--subdir', 'DAGS_FOLDER/dag_try_oop.py', '--cfg-path', '/tmp/tmp65qet_v6']
[2022-11-28T16:38:39.157+0000] {standard_task_runner.py:83} INFO - Job 992: Subtask extractYtApiOperator
[2022-11-28T16:38:39.617+0000] {task_command.py:376} INFO - Running <TaskInstance: dag_try_oop.extractYtApiOperator scheduled__2022-11-28T13:00:00+00:00 [running]> on host 1dd759b3e30c
[2022-11-28T16:38:40.010+0000] {taskinstance.py:1592} INFO - Exporting the following env vars:
AIRFLOW_CTX_DAG_OWNER=***
AIRFLOW_CTX_DAG_ID=dag_try_oop
AIRFLOW_CTX_TASK_ID=extractYtApiOperator
AIRFLOW_CTX_EXECUTION_DATE=2022-11-28T13:00:00+00:00
AIRFLOW_CTX_TRY_NUMBER=1
AIRFLOW_CTX_DAG_RUN_ID=scheduled__2022-11-28T13:00:00+00:00
[2022-11-28T16:38:42.796+0000] {logging_mixin.py:137} INFO - Writing ID data to file...
[2022-11-28T16:38:47.190+0000] {logging_mixin.py:137} INFO - Writing EG data to file...
[2022-11-28T16:38:48.126+0000] {logging_mixin.py:137} INFO - Writing GB data to file...
[2022-11-28T16:38:48.152+0000] {taskinstance.py:1406} INFO - Marking task as SUCCESS. dag_id=dag_try_oop, task_id=extractYtApiOperator, execution_date=20221128T130000, start_date=20221128T163838, end_date=20221128T163848
[2022-11-28T16:38:48.309+0000] {local_task_job.py:159} INFO - Task exited with return code 0
[2022-11-28T16:38:48.446+0000] {taskinstance.py:2623} INFO - 1 downstream tasks scheduled from follow-on schedule check
[2022-11-29T06:31:51.425+0000] {taskinstance.py:1165} INFO - Dependencies all met for <TaskInstance: dag_try_oop.extractYtApiOperator scheduled__2022-11-28T13:00:00+00:00 [queued]>
[2022-11-29T06:31:51.480+0000] {taskinstance.py:1165} INFO - Dependencies all met for <TaskInstance: dag_try_oop.extractYtApiOperator scheduled__2022-11-28T13:00:00+00:00 [queued]>
[2022-11-29T06:31:51.486+0000] {taskinstance.py:1362} INFO - 
--------------------------------------------------------------------------------
[2022-11-29T06:31:51.486+0000] {taskinstance.py:1363} INFO - Starting attempt 1 of 2
[2022-11-29T06:31:51.486+0000] {taskinstance.py:1364} INFO - 
--------------------------------------------------------------------------------
[2022-11-29T06:31:51.548+0000] {taskinstance.py:1383} INFO - Executing <Task(extractYtApiOperator): extractYtApiOperator> on 2022-11-28 13:00:00+00:00
[2022-11-29T06:31:51.583+0000] {standard_task_runner.py:55} INFO - Started process 168 to run task
[2022-11-29T06:31:51.617+0000] {standard_task_runner.py:82} INFO - Running: ['***', 'tasks', 'run', 'dag_try_oop', 'extractYtApiOperator', 'scheduled__2022-11-28T13:00:00+00:00', '--job-id', '1086', '--raw', '--subdir', 'DAGS_FOLDER/dag_try_oop.py', '--cfg-path', '/tmp/tmpqfiagz7e']
[2022-11-29T06:31:51.631+0000] {standard_task_runner.py:83} INFO - Job 1086: Subtask extractYtApiOperator
[2022-11-29T06:31:52.001+0000] {task_command.py:376} INFO - Running <TaskInstance: dag_try_oop.extractYtApiOperator scheduled__2022-11-28T13:00:00+00:00 [running]> on host 92b536e5af67
[2022-11-29T06:31:52.383+0000] {taskinstance.py:1592} INFO - Exporting the following env vars:
AIRFLOW_CTX_DAG_OWNER=***
AIRFLOW_CTX_DAG_ID=dag_try_oop
AIRFLOW_CTX_TASK_ID=extractYtApiOperator
AIRFLOW_CTX_EXECUTION_DATE=2022-11-28T13:00:00+00:00
AIRFLOW_CTX_TRY_NUMBER=1
AIRFLOW_CTX_DAG_RUN_ID=scheduled__2022-11-28T13:00:00+00:00
[2022-11-29T06:31:53.655+0000] {logging_mixin.py:137} INFO - Writing ID data to file...
[2022-11-29T06:31:54.139+0000] {taskinstance.py:1851} ERROR - Task failed with exception
Traceback (most recent call last):
  File "/home/airflow/.local/lib/python3.7/site-packages/urllib3/connectionpool.py", line 710, in urlopen
    chunked=chunked,
  File "/home/airflow/.local/lib/python3.7/site-packages/urllib3/connectionpool.py", line 386, in _make_request
    self._validate_conn(conn)
  File "/home/airflow/.local/lib/python3.7/site-packages/urllib3/connectionpool.py", line 1042, in _validate_conn
    conn.connect()
  File "/home/airflow/.local/lib/python3.7/site-packages/urllib3/connection.py", line 424, in connect
    tls_in_tls=tls_in_tls,
  File "/home/airflow/.local/lib/python3.7/site-packages/urllib3/util/ssl_.py", line 450, in ssl_wrap_socket
    sock, context, tls_in_tls, server_hostname=server_hostname
  File "/home/airflow/.local/lib/python3.7/site-packages/urllib3/util/ssl_.py", line 493, in _ssl_wrap_socket_impl
    return ssl_context.wrap_socket(sock, server_hostname=server_hostname)
  File "/usr/local/lib/python3.7/ssl.py", line 423, in wrap_socket
    session=session
  File "/usr/local/lib/python3.7/ssl.py", line 870, in _create
    self.do_handshake()
  File "/usr/local/lib/python3.7/ssl.py", line 1139, in do_handshake
    self._sslobj.do_handshake()
ssl.SSLError: [SSL: UNSUPPORTED_PROTOCOL] unsupported protocol (_ssl.c:1091)

During handling of the above exception, another exception occurred:

Traceback (most recent call last):
  File "/home/airflow/.local/lib/python3.7/site-packages/requests/adapters.py", line 499, in send
    timeout=timeout,
  File "/home/airflow/.local/lib/python3.7/site-packages/urllib3/connectionpool.py", line 788, in urlopen
    method, url, error=e, _pool=self, _stacktrace=sys.exc_info()[2]
  File "/home/airflow/.local/lib/python3.7/site-packages/urllib3/util/retry.py", line 592, in increment
    raise MaxRetryError(_pool, url, error or ResponseError(cause))
urllib3.exceptions.MaxRetryError: HTTPSConnectionPool(host='www.googleapis.com', port=443): Max retries exceeded with url: /youtube/v3/videos?part=id,statistics,snippet&pageToken=CDIQAA&chart=mostPopular&regionCode=EG&maxResults=50&key=AIzaSyAyC91r6h-lGuNp6hq8mhcO0fpkx4LrO-k (Caused by SSLError(SSLError(1, '[SSL: UNSUPPORTED_PROTOCOL] unsupported protocol (_ssl.c:1091)')))

During handling of the above exception, another exception occurred:

Traceback (most recent call last):
  File "/opt/airflow/plugins/operators/extractYtApiOperator.py", line 95, in execute
    get_data()
  File "/opt/airflow/plugins/operators/extractYtApiOperator.py", line 89, in get_data
    country_data = [",".join(header)] + get_pages(country_code)
  File "/opt/airflow/plugins/operators/extractYtApiOperator.py", line 69, in get_pages
    video_data_page = api_request(next_page_token, country_code)
  File "/opt/airflow/plugins/operators/extractYtApiOperator.py", line 29, in api_request
    request = requests.get(request_url)
  File "/home/airflow/.local/lib/python3.7/site-packages/requests/api.py", line 73, in get
    return request("get", url, params=params, **kwargs)
  File "/home/airflow/.local/lib/python3.7/site-packages/requests/api.py", line 59, in request
    return session.request(method=method, url=url, **kwargs)
  File "/home/airflow/.local/lib/python3.7/site-packages/requests/sessions.py", line 587, in request
    resp = self.send(prep, **send_kwargs)
  File "/home/airflow/.local/lib/python3.7/site-packages/requests/sessions.py", line 701, in send
    r = adapter.send(request, **kwargs)
  File "/home/airflow/.local/lib/python3.7/site-packages/requests/adapters.py", line 563, in send
    raise SSLError(e, request=request)
requests.exceptions.SSLError: HTTPSConnectionPool(host='www.googleapis.com', port=443): Max retries exceeded with url: /youtube/v3/videos?part=id,statistics,snippet&pageToken=CDIQAA&chart=mostPopular&regionCode=EG&maxResults=50&key=AIzaSyAyC91r6h-lGuNp6hq8mhcO0fpkx4LrO-k (Caused by SSLError(SSLError(1, '[SSL: UNSUPPORTED_PROTOCOL] unsupported protocol (_ssl.c:1091)')))
[2022-11-29T06:31:54.217+0000] {taskinstance.py:1406} INFO - Marking task as UP_FOR_RETRY. dag_id=dag_try_oop, task_id=extractYtApiOperator, execution_date=20221128T130000, start_date=20221129T063151, end_date=20221129T063154
[2022-11-29T06:31:54.320+0000] {standard_task_runner.py:105} ERROR - Failed to execute job 1086 for task extractYtApiOperator (HTTPSConnectionPool(host='www.googleapis.com', port=443): Max retries exceeded with url: /youtube/v3/videos?part=id,statistics,snippet&pageToken=CDIQAA&chart=mostPopular&regionCode=EG&maxResults=50&key=AIzaSyAyC91r6h-lGuNp6hq8mhcO0fpkx4LrO-k (Caused by SSLError(SSLError(1, '[SSL: UNSUPPORTED_PROTOCOL] unsupported protocol (_ssl.c:1091)'))); 168)
[2022-11-29T06:31:54.464+0000] {local_task_job.py:159} INFO - Task exited with return code 1
[2022-11-29T06:31:54.670+0000] {taskinstance.py:2623} INFO - 0 downstream tasks scheduled from follow-on schedule check
