[2022-11-28T16:35:29.859+0000] {taskinstance.py:1165} INFO - Dependencies all met for <TaskInstance: dag_try_oop.loadYtApiOperator scheduled__2022-11-27T23:00:00+00:00 [queued]>
[2022-11-28T16:35:29.895+0000] {taskinstance.py:1165} INFO - Dependencies all met for <TaskInstance: dag_try_oop.loadYtApiOperator scheduled__2022-11-27T23:00:00+00:00 [queued]>
[2022-11-28T16:35:29.897+0000] {taskinstance.py:1362} INFO - 
--------------------------------------------------------------------------------
[2022-11-28T16:35:29.897+0000] {taskinstance.py:1363} INFO - Starting attempt 2 of 2
[2022-11-28T16:35:29.897+0000] {taskinstance.py:1364} INFO - 
--------------------------------------------------------------------------------
[2022-11-28T16:35:30.753+0000] {taskinstance.py:1383} INFO - Executing <Task(loadYtApiOperator): loadYtApiOperator> on 2022-11-27 23:00:00+00:00
[2022-11-28T16:35:30.825+0000] {standard_task_runner.py:55} INFO - Started process 1129 to run task
[2022-11-28T16:35:30.886+0000] {standard_task_runner.py:82} INFO - Running: ['***', 'tasks', 'run', 'dag_try_oop', 'loadYtApiOperator', 'scheduled__2022-11-27T23:00:00+00:00', '--job-id', '935', '--raw', '--subdir', 'DAGS_FOLDER/dag_try_oop.py', '--cfg-path', '/tmp/tmpkfc8vz52']
[2022-11-28T16:35:30.908+0000] {standard_task_runner.py:83} INFO - Job 935: Subtask loadYtApiOperator
[2022-11-28T16:35:31.476+0000] {task_command.py:376} INFO - Running <TaskInstance: dag_try_oop.loadYtApiOperator scheduled__2022-11-27T23:00:00+00:00 [running]> on host 1dd759b3e30c
[2022-11-28T16:35:31.711+0000] {taskinstance.py:1592} INFO - Exporting the following env vars:
AIRFLOW_CTX_DAG_OWNER=***
AIRFLOW_CTX_DAG_ID=dag_try_oop
AIRFLOW_CTX_TASK_ID=loadYtApiOperator
AIRFLOW_CTX_EXECUTION_DATE=2022-11-27T23:00:00+00:00
AIRFLOW_CTX_TRY_NUMBER=2
AIRFLOW_CTX_DAG_RUN_ID=scheduled__2022-11-27T23:00:00+00:00
[2022-11-28T16:35:31.734+0000] {taskinstance.py:1851} ERROR - Task failed with exception
Traceback (most recent call last):
  File "/opt/airflow/plugins/operators/loadYtApiOperator.py", line 70, in execute
    row.split(",")[11])
IndexError: list index out of range
[2022-11-28T16:35:31.745+0000] {taskinstance.py:1406} INFO - Marking task as FAILED. dag_id=dag_try_oop, task_id=loadYtApiOperator, execution_date=20221127T230000, start_date=20221128T163529, end_date=20221128T163531
[2022-11-28T16:35:31.777+0000] {standard_task_runner.py:105} ERROR - Failed to execute job 935 for task loadYtApiOperator (list index out of range; 1129)
[2022-11-28T16:35:31.836+0000] {local_task_job.py:159} INFO - Task exited with return code 1
[2022-11-28T16:35:32.110+0000] {taskinstance.py:2623} INFO - 0 downstream tasks scheduled from follow-on schedule check
