[2022-11-28T16:30:24.265+0000] {taskinstance.py:1165} INFO - Dependencies all met for <TaskInstance: dag_try_oop.loadYtApiOperator scheduled__2022-11-28T03:00:00+00:00 [queued]>
[2022-11-28T16:30:24.522+0000] {taskinstance.py:1165} INFO - Dependencies all met for <TaskInstance: dag_try_oop.loadYtApiOperator scheduled__2022-11-28T03:00:00+00:00 [queued]>
[2022-11-28T16:30:24.535+0000] {taskinstance.py:1362} INFO - 
--------------------------------------------------------------------------------
[2022-11-28T16:30:24.538+0000] {taskinstance.py:1363} INFO - Starting attempt 1 of 2
[2022-11-28T16:30:24.560+0000] {taskinstance.py:1364} INFO - 
--------------------------------------------------------------------------------
[2022-11-28T16:30:24.960+0000] {taskinstance.py:1383} INFO - Executing <Task(loadYtApiOperator): loadYtApiOperator> on 2022-11-28 03:00:00+00:00
[2022-11-28T16:30:25.121+0000] {standard_task_runner.py:55} INFO - Started process 658 to run task
[2022-11-28T16:30:25.274+0000] {standard_task_runner.py:82} INFO - Running: ['***', 'tasks', 'run', 'dag_try_oop', 'loadYtApiOperator', 'scheduled__2022-11-28T03:00:00+00:00', '--job-id', '823', '--raw', '--subdir', 'DAGS_FOLDER/dag_try_oop.py', '--cfg-path', '/tmp/tmpmwqdquz4']
[2022-11-28T16:30:25.317+0000] {standard_task_runner.py:83} INFO - Job 823: Subtask loadYtApiOperator
[2022-11-28T16:30:26.840+0000] {task_command.py:376} INFO - Running <TaskInstance: dag_try_oop.loadYtApiOperator scheduled__2022-11-28T03:00:00+00:00 [running]> on host 1dd759b3e30c
[2022-11-28T16:30:28.823+0000] {taskinstance.py:1592} INFO - Exporting the following env vars:
AIRFLOW_CTX_DAG_OWNER=***
AIRFLOW_CTX_DAG_ID=dag_try_oop
AIRFLOW_CTX_TASK_ID=loadYtApiOperator
AIRFLOW_CTX_EXECUTION_DATE=2022-11-28T03:00:00+00:00
AIRFLOW_CTX_TRY_NUMBER=1
AIRFLOW_CTX_DAG_RUN_ID=scheduled__2022-11-28T03:00:00+00:00
[2022-11-28T16:30:28.897+0000] {taskinstance.py:1851} ERROR - Task failed with exception
Traceback (most recent call last):
  File "/opt/airflow/plugins/operators/loadYtApiOperator.py", line 70, in execute
    row.split(",")[11])
IndexError: list index out of range
[2022-11-28T16:30:29.086+0000] {taskinstance.py:1406} INFO - Marking task as UP_FOR_RETRY. dag_id=dag_try_oop, task_id=loadYtApiOperator, execution_date=20221128T030000, start_date=20221128T163024, end_date=20221128T163029
[2022-11-28T16:30:30.053+0000] {standard_task_runner.py:105} ERROR - Failed to execute job 823 for task loadYtApiOperator (list index out of range; 658)
[2022-11-28T16:30:30.376+0000] {local_task_job.py:159} INFO - Task exited with return code 1
[2022-11-28T16:30:30.783+0000] {taskinstance.py:2623} INFO - 0 downstream tasks scheduled from follow-on schedule check
