[2022-11-28T16:23:08.162+0000] {taskinstance.py:1165} INFO - Dependencies all met for <TaskInstance: dag_try_oop.extractYtApiOperator scheduled__2022-11-28T03:10:00+00:00 [queued]>
[2022-11-28T16:23:08.658+0000] {taskinstance.py:1165} INFO - Dependencies all met for <TaskInstance: dag_try_oop.extractYtApiOperator scheduled__2022-11-28T03:10:00+00:00 [queued]>
[2022-11-28T16:23:08.665+0000] {taskinstance.py:1362} INFO - 
--------------------------------------------------------------------------------
[2022-11-28T16:23:08.678+0000] {taskinstance.py:1363} INFO - Starting attempt 1 of 2
[2022-11-28T16:23:08.699+0000] {taskinstance.py:1364} INFO - 
--------------------------------------------------------------------------------
[2022-11-28T16:23:09.341+0000] {taskinstance.py:1383} INFO - Executing <Task(extractYtApiOperator): extractYtApiOperator> on 2022-11-28 03:10:00+00:00
[2022-11-28T16:23:09.526+0000] {standard_task_runner.py:55} INFO - Started process 119 to run task
[2022-11-28T16:23:09.816+0000] {standard_task_runner.py:82} INFO - Running: ['***', 'tasks', 'run', 'dag_try_oop', 'extractYtApiOperator', 'scheduled__2022-11-28T03:10:00+00:00', '--job-id', '720', '--raw', '--subdir', 'DAGS_FOLDER/dag_try_oop.py', '--cfg-path', '/tmp/tmpuz91qwf6']
[2022-11-28T16:23:10.075+0000] {standard_task_runner.py:83} INFO - Job 720: Subtask extractYtApiOperator
[2022-11-28T16:23:13.605+0000] {task_command.py:376} INFO - Running <TaskInstance: dag_try_oop.extractYtApiOperator scheduled__2022-11-28T03:10:00+00:00 [running]> on host 1dd759b3e30c
[2022-11-28T16:23:16.695+0000] {taskinstance.py:1592} INFO - Exporting the following env vars:
AIRFLOW_CTX_DAG_OWNER=***
AIRFLOW_CTX_DAG_ID=dag_try_oop
AIRFLOW_CTX_TASK_ID=extractYtApiOperator
AIRFLOW_CTX_EXECUTION_DATE=2022-11-28T03:10:00+00:00
AIRFLOW_CTX_TRY_NUMBER=1
AIRFLOW_CTX_DAG_RUN_ID=scheduled__2022-11-28T03:10:00+00:00
[2022-11-28T16:24:01.798+0000] {taskinstance.py:1851} ERROR - Task failed with exception
Traceback (most recent call last):
  File "/home/airflow/.local/lib/python3.7/site-packages/urllib3/connectionpool.py", line 710, in urlopen
    chunked=chunked,
  File "/home/airflow/.local/lib/python3.7/site-packages/urllib3/connectionpool.py", line 449, in _make_request
    six.raise_from(e, None)
  File "<string>", line 3, in raise_from
  File "/home/airflow/.local/lib/python3.7/site-packages/urllib3/connectionpool.py", line 444, in _make_request
    httplib_response = conn.getresponse()
  File "/usr/local/lib/python3.7/http/client.py", line 1373, in getresponse
    response.begin()
  File "/usr/local/lib/python3.7/http/client.py", line 319, in begin
    version, status, reason = self._read_status()
  File "/usr/local/lib/python3.7/http/client.py", line 288, in _read_status
    raise RemoteDisconnected("Remote end closed connection without"
http.client.RemoteDisconnected: Remote end closed connection without response

During handling of the above exception, another exception occurred:

Traceback (most recent call last):
  File "/home/airflow/.local/lib/python3.7/site-packages/requests/adapters.py", line 499, in send
    timeout=timeout,
  File "/home/airflow/.local/lib/python3.7/site-packages/urllib3/connectionpool.py", line 788, in urlopen
    method, url, error=e, _pool=self, _stacktrace=sys.exc_info()[2]
  File "/home/airflow/.local/lib/python3.7/site-packages/urllib3/util/retry.py", line 550, in increment
    raise six.reraise(type(error), error, _stacktrace)
  File "/home/airflow/.local/lib/python3.7/site-packages/urllib3/packages/six.py", line 769, in reraise
    raise value.with_traceback(tb)
  File "/home/airflow/.local/lib/python3.7/site-packages/urllib3/connectionpool.py", line 710, in urlopen
    chunked=chunked,
  File "/home/airflow/.local/lib/python3.7/site-packages/urllib3/connectionpool.py", line 449, in _make_request
    six.raise_from(e, None)
  File "<string>", line 3, in raise_from
  File "/home/airflow/.local/lib/python3.7/site-packages/urllib3/connectionpool.py", line 444, in _make_request
    httplib_response = conn.getresponse()
  File "/usr/local/lib/python3.7/http/client.py", line 1373, in getresponse
    response.begin()
  File "/usr/local/lib/python3.7/http/client.py", line 319, in begin
    version, status, reason = self._read_status()
  File "/usr/local/lib/python3.7/http/client.py", line 288, in _read_status
    raise RemoteDisconnected("Remote end closed connection without"
urllib3.exceptions.ProtocolError: ('Connection aborted.', RemoteDisconnected('Remote end closed connection without response'))

During handling of the above exception, another exception occurred:

Traceback (most recent call last):
  File "/opt/airflow/plugins/operators/extractYtApiOperator.py", line 95, in execute
    get_data()
  File "/opt/airflow/plugins/operators/extractYtApiOperator.py", line 89, in get_data
    country_data = [",".join(header)] + get_pages(country_code)
  File "/opt/airflow/plugins/operators/extractYtApiOperator.py", line 69, in get_pages
    video_data_page = api_request(next_page_token, country_code)
  File "/opt/airflow/plugins/operators/extractYtApiOperator.py", line 29, in api_request
    request = requests.get(request_url)
  File "/home/airflow/.local/lib/python3.7/site-packages/requests/api.py", line 73, in get
    return request("get", url, params=params, **kwargs)
  File "/home/airflow/.local/lib/python3.7/site-packages/requests/api.py", line 59, in request
    return session.request(method=method, url=url, **kwargs)
  File "/home/airflow/.local/lib/python3.7/site-packages/requests/sessions.py", line 587, in request
    resp = self.send(prep, **send_kwargs)
  File "/home/airflow/.local/lib/python3.7/site-packages/requests/sessions.py", line 701, in send
    r = adapter.send(request, **kwargs)
  File "/home/airflow/.local/lib/python3.7/site-packages/requests/adapters.py", line 547, in send
    raise ConnectionError(err, request=request)
requests.exceptions.ConnectionError: ('Connection aborted.', RemoteDisconnected('Remote end closed connection without response'))
[2022-11-28T16:24:12.751+0000] {taskinstance.py:1406} INFO - Marking task as UP_FOR_RETRY. dag_id=dag_try_oop, task_id=extractYtApiOperator, execution_date=20221128T031000, start_date=20221128T162308, end_date=20221128T162412
[2022-11-28T16:24:15.060+0000] {standard_task_runner.py:105} ERROR - Failed to execute job 720 for task extractYtApiOperator (('Connection aborted.', RemoteDisconnected('Remote end closed connection without response')); 119)
[2022-11-28T16:24:15.649+0000] {local_task_job.py:159} INFO - Task exited with return code 1
[2022-11-28T16:24:16.108+0000] {taskinstance.py:2623} INFO - 0 downstream tasks scheduled from follow-on schedule check
