[2022-11-28T16:38:40.398+0000] {taskinstance.py:1165} INFO - Dependencies all met for <TaskInstance: dag_try_oop.extractYtApiOperator scheduled__2022-11-28T14:00:00+00:00 [queued]>
[2022-11-28T16:38:40.437+0000] {taskinstance.py:1165} INFO - Dependencies all met for <TaskInstance: dag_try_oop.extractYtApiOperator scheduled__2022-11-28T14:00:00+00:00 [queued]>
[2022-11-28T16:38:40.438+0000] {taskinstance.py:1362} INFO - 
--------------------------------------------------------------------------------
[2022-11-28T16:38:40.438+0000] {taskinstance.py:1363} INFO - Starting attempt 1 of 2
[2022-11-28T16:38:40.439+0000] {taskinstance.py:1364} INFO - 
--------------------------------------------------------------------------------
[2022-11-28T16:38:40.484+0000] {taskinstance.py:1383} INFO - Executing <Task(extractYtApiOperator): extractYtApiOperator> on 2022-11-28 14:00:00+00:00
[2022-11-28T16:38:40.506+0000] {standard_task_runner.py:55} INFO - Started process 1392 to run task
[2022-11-28T16:38:40.524+0000] {standard_task_runner.py:82} INFO - Running: ['***', 'tasks', 'run', 'dag_try_oop', 'extractYtApiOperator', 'scheduled__2022-11-28T14:00:00+00:00', '--job-id', '993', '--raw', '--subdir', 'DAGS_FOLDER/dag_try_oop.py', '--cfg-path', '/tmp/tmpkonq5zdr']
[2022-11-28T16:38:40.533+0000] {standard_task_runner.py:83} INFO - Job 993: Subtask extractYtApiOperator
[2022-11-28T16:38:40.831+0000] {task_command.py:376} INFO - Running <TaskInstance: dag_try_oop.extractYtApiOperator scheduled__2022-11-28T14:00:00+00:00 [running]> on host 1dd759b3e30c
[2022-11-28T16:38:41.191+0000] {taskinstance.py:1592} INFO - Exporting the following env vars:
AIRFLOW_CTX_DAG_OWNER=***
AIRFLOW_CTX_DAG_ID=dag_try_oop
AIRFLOW_CTX_TASK_ID=extractYtApiOperator
AIRFLOW_CTX_EXECUTION_DATE=2022-11-28T14:00:00+00:00
AIRFLOW_CTX_TRY_NUMBER=1
AIRFLOW_CTX_DAG_RUN_ID=scheduled__2022-11-28T14:00:00+00:00
[2022-11-28T16:38:45.020+0000] {logging_mixin.py:137} INFO - Writing ID data to file...
[2022-11-28T16:38:46.713+0000] {logging_mixin.py:137} INFO - Writing EG data to file...
[2022-11-28T16:38:47.754+0000] {logging_mixin.py:137} INFO - Writing GB data to file...
[2022-11-28T16:38:47.773+0000] {taskinstance.py:1406} INFO - Marking task as SUCCESS. dag_id=dag_try_oop, task_id=extractYtApiOperator, execution_date=20221128T140000, start_date=20221128T163840, end_date=20221128T163847
[2022-11-28T16:38:47.836+0000] {local_task_job.py:159} INFO - Task exited with return code 0
[2022-11-28T16:38:47.873+0000] {taskinstance.py:2623} INFO - 1 downstream tasks scheduled from follow-on schedule check
[2022-11-29T06:31:53.137+0000] {taskinstance.py:1165} INFO - Dependencies all met for <TaskInstance: dag_try_oop.extractYtApiOperator scheduled__2022-11-28T14:00:00+00:00 [queued]>
[2022-11-29T06:31:53.229+0000] {taskinstance.py:1165} INFO - Dependencies all met for <TaskInstance: dag_try_oop.extractYtApiOperator scheduled__2022-11-28T14:00:00+00:00 [queued]>
[2022-11-29T06:31:53.231+0000] {taskinstance.py:1362} INFO - 
--------------------------------------------------------------------------------
[2022-11-29T06:31:53.237+0000] {taskinstance.py:1363} INFO - Starting attempt 1 of 2
[2022-11-29T06:31:53.239+0000] {taskinstance.py:1364} INFO - 
--------------------------------------------------------------------------------
[2022-11-29T06:31:53.360+0000] {taskinstance.py:1383} INFO - Executing <Task(extractYtApiOperator): extractYtApiOperator> on 2022-11-28 14:00:00+00:00
[2022-11-29T06:31:53.403+0000] {standard_task_runner.py:55} INFO - Started process 171 to run task
[2022-11-29T06:31:53.429+0000] {standard_task_runner.py:82} INFO - Running: ['***', 'tasks', 'run', 'dag_try_oop', 'extractYtApiOperator', 'scheduled__2022-11-28T14:00:00+00:00', '--job-id', '1087', '--raw', '--subdir', 'DAGS_FOLDER/dag_try_oop.py', '--cfg-path', '/tmp/tmppmwq3sa9']
[2022-11-29T06:31:53.444+0000] {standard_task_runner.py:83} INFO - Job 1087: Subtask extractYtApiOperator
[2022-11-29T06:31:53.834+0000] {task_command.py:376} INFO - Running <TaskInstance: dag_try_oop.extractYtApiOperator scheduled__2022-11-28T14:00:00+00:00 [running]> on host 92b536e5af67
[2022-11-29T06:31:54.246+0000] {taskinstance.py:1592} INFO - Exporting the following env vars:
AIRFLOW_CTX_DAG_OWNER=***
AIRFLOW_CTX_DAG_ID=dag_try_oop
AIRFLOW_CTX_TASK_ID=extractYtApiOperator
AIRFLOW_CTX_EXECUTION_DATE=2022-11-28T14:00:00+00:00
AIRFLOW_CTX_TRY_NUMBER=1
AIRFLOW_CTX_DAG_RUN_ID=scheduled__2022-11-28T14:00:00+00:00
[2022-11-29T06:31:55.132+0000] {taskinstance.py:1851} ERROR - Task failed with exception
Traceback (most recent call last):
  File "/home/airflow/.local/lib/python3.7/site-packages/urllib3/connectionpool.py", line 710, in urlopen
    chunked=chunked,
  File "/home/airflow/.local/lib/python3.7/site-packages/urllib3/connectionpool.py", line 386, in _make_request
    self._validate_conn(conn)
  File "/home/airflow/.local/lib/python3.7/site-packages/urllib3/connectionpool.py", line 1042, in _validate_conn
    conn.connect()
  File "/home/airflow/.local/lib/python3.7/site-packages/urllib3/connection.py", line 424, in connect
    tls_in_tls=tls_in_tls,
  File "/home/airflow/.local/lib/python3.7/site-packages/urllib3/util/ssl_.py", line 450, in ssl_wrap_socket
    sock, context, tls_in_tls, server_hostname=server_hostname
  File "/home/airflow/.local/lib/python3.7/site-packages/urllib3/util/ssl_.py", line 493, in _ssl_wrap_socket_impl
    return ssl_context.wrap_socket(sock, server_hostname=server_hostname)
  File "/usr/local/lib/python3.7/ssl.py", line 423, in wrap_socket
    session=session
  File "/usr/local/lib/python3.7/ssl.py", line 870, in _create
    self.do_handshake()
  File "/usr/local/lib/python3.7/ssl.py", line 1139, in do_handshake
    self._sslobj.do_handshake()
ssl.SSLError: [SSL: UNSUPPORTED_PROTOCOL] unsupported protocol (_ssl.c:1091)

During handling of the above exception, another exception occurred:

Traceback (most recent call last):
  File "/home/airflow/.local/lib/python3.7/site-packages/requests/adapters.py", line 499, in send
    timeout=timeout,
  File "/home/airflow/.local/lib/python3.7/site-packages/urllib3/connectionpool.py", line 788, in urlopen
    method, url, error=e, _pool=self, _stacktrace=sys.exc_info()[2]
  File "/home/airflow/.local/lib/python3.7/site-packages/urllib3/util/retry.py", line 592, in increment
    raise MaxRetryError(_pool, url, error or ResponseError(cause))
urllib3.exceptions.MaxRetryError: HTTPSConnectionPool(host='www.googleapis.com', port=443): Max retries exceeded with url: /youtube/v3/videos?part=id,statistics,snippet&pageToken=CGQQAA&chart=mostPopular&regionCode=ID&maxResults=50&key=AIzaSyAyC91r6h-lGuNp6hq8mhcO0fpkx4LrO-k (Caused by SSLError(SSLError(1, '[SSL: UNSUPPORTED_PROTOCOL] unsupported protocol (_ssl.c:1091)')))

During handling of the above exception, another exception occurred:

Traceback (most recent call last):
  File "/opt/airflow/plugins/operators/extractYtApiOperator.py", line 95, in execute
    get_data()
  File "/opt/airflow/plugins/operators/extractYtApiOperator.py", line 89, in get_data
    country_data = [",".join(header)] + get_pages(country_code)
  File "/opt/airflow/plugins/operators/extractYtApiOperator.py", line 69, in get_pages
    video_data_page = api_request(next_page_token, country_code)
  File "/opt/airflow/plugins/operators/extractYtApiOperator.py", line 29, in api_request
    request = requests.get(request_url)
  File "/home/airflow/.local/lib/python3.7/site-packages/requests/api.py", line 73, in get
    return request("get", url, params=params, **kwargs)
  File "/home/airflow/.local/lib/python3.7/site-packages/requests/api.py", line 59, in request
    return session.request(method=method, url=url, **kwargs)
  File "/home/airflow/.local/lib/python3.7/site-packages/requests/sessions.py", line 587, in request
    resp = self.send(prep, **send_kwargs)
  File "/home/airflow/.local/lib/python3.7/site-packages/requests/sessions.py", line 701, in send
    r = adapter.send(request, **kwargs)
  File "/home/airflow/.local/lib/python3.7/site-packages/requests/adapters.py", line 563, in send
    raise SSLError(e, request=request)
requests.exceptions.SSLError: HTTPSConnectionPool(host='www.googleapis.com', port=443): Max retries exceeded with url: /youtube/v3/videos?part=id,statistics,snippet&pageToken=CGQQAA&chart=mostPopular&regionCode=ID&maxResults=50&key=AIzaSyAyC91r6h-lGuNp6hq8mhcO0fpkx4LrO-k (Caused by SSLError(SSLError(1, '[SSL: UNSUPPORTED_PROTOCOL] unsupported protocol (_ssl.c:1091)')))
[2022-11-29T06:31:55.187+0000] {taskinstance.py:1406} INFO - Marking task as UP_FOR_RETRY. dag_id=dag_try_oop, task_id=extractYtApiOperator, execution_date=20221128T140000, start_date=20221129T063153, end_date=20221129T063155
[2022-11-29T06:31:55.401+0000] {standard_task_runner.py:105} ERROR - Failed to execute job 1087 for task extractYtApiOperator (HTTPSConnectionPool(host='www.googleapis.com', port=443): Max retries exceeded with url: /youtube/v3/videos?part=id,statistics,snippet&pageToken=CGQQAA&chart=mostPopular&regionCode=ID&maxResults=50&key=AIzaSyAyC91r6h-lGuNp6hq8mhcO0fpkx4LrO-k (Caused by SSLError(SSLError(1, '[SSL: UNSUPPORTED_PROTOCOL] unsupported protocol (_ssl.c:1091)'))); 171)
[2022-11-29T06:31:55.472+0000] {local_task_job.py:159} INFO - Task exited with return code 1
[2022-11-29T06:31:55.696+0000] {taskinstance.py:2623} INFO - 0 downstream tasks scheduled from follow-on schedule check
