[2022-11-27T12:03:15.341+0000] {taskinstance.py:1165} INFO - Dependencies all met for <TaskInstance: using_pandas_demo.getDataToLocal manual__2022-11-27T11:58:03.390018+00:00 [queued]>
[2022-11-27T12:03:15.352+0000] {taskinstance.py:1165} INFO - Dependencies all met for <TaskInstance: using_pandas_demo.getDataToLocal manual__2022-11-27T11:58:03.390018+00:00 [queued]>
[2022-11-27T12:03:15.361+0000] {taskinstance.py:1362} INFO - 
--------------------------------------------------------------------------------
[2022-11-27T12:03:15.361+0000] {taskinstance.py:1363} INFO - Starting attempt 2 of 2
[2022-11-27T12:03:15.362+0000] {taskinstance.py:1364} INFO - 
--------------------------------------------------------------------------------
[2022-11-27T12:03:15.388+0000] {taskinstance.py:1383} INFO - Executing <Task(PythonOperator): getDataToLocal> on 2022-11-27 11:58:03.390018+00:00
[2022-11-27T12:03:15.394+0000] {standard_task_runner.py:55} INFO - Started process 1261 to run task
[2022-11-27T12:03:15.403+0000] {standard_task_runner.py:82} INFO - Running: ['***', 'tasks', 'run', 'using_pandas_demo', 'getDataToLocal', 'manual__2022-11-27T11:58:03.390018+00:00', '--job-id', '328', '--raw', '--subdir', 'DAGS_FOLDER/dag_pandas_demo.py', '--cfg-path', '/tmp/tmp8o54jo39']
[2022-11-27T12:03:15.406+0000] {standard_task_runner.py:83} INFO - Job 328: Subtask getDataToLocal
[2022-11-27T12:03:15.508+0000] {task_command.py:376} INFO - Running <TaskInstance: using_pandas_demo.getDataToLocal manual__2022-11-27T11:58:03.390018+00:00 [running]> on host 8063ad561fea
[2022-11-27T12:03:15.643+0000] {taskinstance.py:1592} INFO - Exporting the following env vars:
AIRFLOW_CTX_DAG_OWNER=***
AIRFLOW_CTX_DAG_ID=using_pandas_demo
AIRFLOW_CTX_TASK_ID=getDataToLocal
AIRFLOW_CTX_EXECUTION_DATE=2022-11-27T11:58:03.390018+00:00
AIRFLOW_CTX_TRY_NUMBER=2
AIRFLOW_CTX_DAG_RUN_ID=manual__2022-11-27T11:58:03.390018+00:00
[2022-11-27T12:03:24.687+0000] {taskinstance.py:1851} ERROR - Task failed with exception
Traceback (most recent call last):
  File "/home/airflow/.local/lib/python3.7/site-packages/airflow/operators/python.py", line 175, in execute
    return_value = self.execute_callable()
  File "/home/airflow/.local/lib/python3.7/site-packages/airflow/operators/python.py", line 193, in execute_callable
    return self.python_callable(*self.op_args, **self.op_kwargs)
  File "/opt/airflow/dags/dag_pandas_demo.py", line 37, in getDataToLocal
    df.to_csv("/home/wiweka/Downloads/drivers.csv", sep=',' ,escapechar='\\', quoting=csv.QUOTE_ALL, encoding='utf-8' )
  File "/home/airflow/.local/lib/python3.7/site-packages/pandas/core/generic.py", line 3482, in to_csv
    storage_options=storage_options,
  File "/home/airflow/.local/lib/python3.7/site-packages/pandas/io/formats/format.py", line 1105, in to_csv
    csv_formatter.save()
  File "/home/airflow/.local/lib/python3.7/site-packages/pandas/io/formats/csvs.py", line 243, in save
    storage_options=self.storage_options,
  File "/home/airflow/.local/lib/python3.7/site-packages/pandas/io/common.py", line 707, in get_handle
    newline="",
FileNotFoundError: [Errno 2] No such file or directory: '/home/wiweka/Downloads/drivers.csv'
[2022-11-27T12:03:24.703+0000] {taskinstance.py:1406} INFO - Marking task as FAILED. dag_id=using_pandas_demo, task_id=getDataToLocal, execution_date=20221127T115803, start_date=20221127T120315, end_date=20221127T120324
[2022-11-27T12:03:24.742+0000] {standard_task_runner.py:105} ERROR - Failed to execute job 328 for task getDataToLocal ([Errno 2] No such file or directory: '/home/wiweka/Downloads/drivers.csv'; 1261)
[2022-11-27T12:03:24.795+0000] {local_task_job.py:159} INFO - Task exited with return code 1
[2022-11-27T12:03:24.828+0000] {taskinstance.py:2623} INFO - 0 downstream tasks scheduled from follow-on schedule check
