[2022-11-28T16:23:07.802+0000] {taskinstance.py:1165} INFO - Dependencies all met for <TaskInstance: dag_try_oop.extractYtApiOperator scheduled__2022-11-28T03:00:00+00:00 [queued]>
[2022-11-28T16:23:08.309+0000] {taskinstance.py:1165} INFO - Dependencies all met for <TaskInstance: dag_try_oop.extractYtApiOperator scheduled__2022-11-28T03:00:00+00:00 [queued]>
[2022-11-28T16:23:08.325+0000] {taskinstance.py:1362} INFO - 
--------------------------------------------------------------------------------
[2022-11-28T16:23:08.335+0000] {taskinstance.py:1363} INFO - Starting attempt 1 of 2
[2022-11-28T16:23:08.453+0000] {taskinstance.py:1364} INFO - 
--------------------------------------------------------------------------------
[2022-11-28T16:23:08.984+0000] {taskinstance.py:1383} INFO - Executing <Task(extractYtApiOperator): extractYtApiOperator> on 2022-11-28 03:00:00+00:00
[2022-11-28T16:23:09.282+0000] {standard_task_runner.py:55} INFO - Started process 118 to run task
[2022-11-28T16:23:09.462+0000] {standard_task_runner.py:82} INFO - Running: ['***', 'tasks', 'run', 'dag_try_oop', 'extractYtApiOperator', 'scheduled__2022-11-28T03:00:00+00:00', '--job-id', '715', '--raw', '--subdir', 'DAGS_FOLDER/dag_try_oop.py', '--cfg-path', '/tmp/tmp52krqnix']
[2022-11-28T16:23:09.524+0000] {standard_task_runner.py:83} INFO - Job 715: Subtask extractYtApiOperator
[2022-11-28T16:23:13.784+0000] {task_command.py:376} INFO - Running <TaskInstance: dag_try_oop.extractYtApiOperator scheduled__2022-11-28T03:00:00+00:00 [running]> on host 1dd759b3e30c
[2022-11-28T16:23:16.549+0000] {taskinstance.py:1592} INFO - Exporting the following env vars:
AIRFLOW_CTX_DAG_OWNER=***
AIRFLOW_CTX_DAG_ID=dag_try_oop
AIRFLOW_CTX_TASK_ID=extractYtApiOperator
AIRFLOW_CTX_EXECUTION_DATE=2022-11-28T03:00:00+00:00
AIRFLOW_CTX_TRY_NUMBER=1
AIRFLOW_CTX_DAG_RUN_ID=scheduled__2022-11-28T03:00:00+00:00
[2022-11-28T16:23:44.712+0000] {taskinstance.py:1851} ERROR - Task failed with exception
Traceback (most recent call last):
  File "/home/airflow/.local/lib/python3.7/site-packages/urllib3/connectionpool.py", line 710, in urlopen
    chunked=chunked,
  File "/home/airflow/.local/lib/python3.7/site-packages/urllib3/connectionpool.py", line 386, in _make_request
    self._validate_conn(conn)
  File "/home/airflow/.local/lib/python3.7/site-packages/urllib3/connectionpool.py", line 1042, in _validate_conn
    conn.connect()
  File "/home/airflow/.local/lib/python3.7/site-packages/urllib3/connection.py", line 424, in connect
    tls_in_tls=tls_in_tls,
  File "/home/airflow/.local/lib/python3.7/site-packages/urllib3/util/ssl_.py", line 450, in ssl_wrap_socket
    sock, context, tls_in_tls, server_hostname=server_hostname
  File "/home/airflow/.local/lib/python3.7/site-packages/urllib3/util/ssl_.py", line 493, in _ssl_wrap_socket_impl
    return ssl_context.wrap_socket(sock, server_hostname=server_hostname)
  File "/usr/local/lib/python3.7/ssl.py", line 423, in wrap_socket
    session=session
  File "/usr/local/lib/python3.7/ssl.py", line 870, in _create
    self.do_handshake()
  File "/usr/local/lib/python3.7/ssl.py", line 1139, in do_handshake
    self._sslobj.do_handshake()
OSError: [Errno 0] Error

During handling of the above exception, another exception occurred:

Traceback (most recent call last):
  File "/home/airflow/.local/lib/python3.7/site-packages/requests/adapters.py", line 499, in send
    timeout=timeout,
  File "/home/airflow/.local/lib/python3.7/site-packages/urllib3/connectionpool.py", line 788, in urlopen
    method, url, error=e, _pool=self, _stacktrace=sys.exc_info()[2]
  File "/home/airflow/.local/lib/python3.7/site-packages/urllib3/util/retry.py", line 550, in increment
    raise six.reraise(type(error), error, _stacktrace)
  File "/home/airflow/.local/lib/python3.7/site-packages/urllib3/packages/six.py", line 769, in reraise
    raise value.with_traceback(tb)
  File "/home/airflow/.local/lib/python3.7/site-packages/urllib3/connectionpool.py", line 710, in urlopen
    chunked=chunked,
  File "/home/airflow/.local/lib/python3.7/site-packages/urllib3/connectionpool.py", line 386, in _make_request
    self._validate_conn(conn)
  File "/home/airflow/.local/lib/python3.7/site-packages/urllib3/connectionpool.py", line 1042, in _validate_conn
    conn.connect()
  File "/home/airflow/.local/lib/python3.7/site-packages/urllib3/connection.py", line 424, in connect
    tls_in_tls=tls_in_tls,
  File "/home/airflow/.local/lib/python3.7/site-packages/urllib3/util/ssl_.py", line 450, in ssl_wrap_socket
    sock, context, tls_in_tls, server_hostname=server_hostname
  File "/home/airflow/.local/lib/python3.7/site-packages/urllib3/util/ssl_.py", line 493, in _ssl_wrap_socket_impl
    return ssl_context.wrap_socket(sock, server_hostname=server_hostname)
  File "/usr/local/lib/python3.7/ssl.py", line 423, in wrap_socket
    session=session
  File "/usr/local/lib/python3.7/ssl.py", line 870, in _create
    self.do_handshake()
  File "/usr/local/lib/python3.7/ssl.py", line 1139, in do_handshake
    self._sslobj.do_handshake()
urllib3.exceptions.ProtocolError: ('Connection aborted.', OSError(0, 'Error'))

During handling of the above exception, another exception occurred:

Traceback (most recent call last):
  File "/opt/airflow/plugins/operators/extractYtApiOperator.py", line 95, in execute
    get_data()
  File "/opt/airflow/plugins/operators/extractYtApiOperator.py", line 89, in get_data
    country_data = [",".join(header)] + get_pages(country_code)
  File "/opt/airflow/plugins/operators/extractYtApiOperator.py", line 69, in get_pages
    video_data_page = api_request(next_page_token, country_code)
  File "/opt/airflow/plugins/operators/extractYtApiOperator.py", line 29, in api_request
    request = requests.get(request_url)
  File "/home/airflow/.local/lib/python3.7/site-packages/requests/api.py", line 73, in get
    return request("get", url, params=params, **kwargs)
  File "/home/airflow/.local/lib/python3.7/site-packages/requests/api.py", line 59, in request
    return session.request(method=method, url=url, **kwargs)
  File "/home/airflow/.local/lib/python3.7/site-packages/requests/sessions.py", line 587, in request
    resp = self.send(prep, **send_kwargs)
  File "/home/airflow/.local/lib/python3.7/site-packages/requests/sessions.py", line 701, in send
    r = adapter.send(request, **kwargs)
  File "/home/airflow/.local/lib/python3.7/site-packages/requests/adapters.py", line 547, in send
    raise ConnectionError(err, request=request)
requests.exceptions.ConnectionError: ('Connection aborted.', OSError(0, 'Error'))
[2022-11-28T16:24:14.907+0000] {local_task_job.py:159} INFO - Task exited with return code Negsignal.SIGKILL
[2022-11-28T16:24:15.872+0000] {taskinstance.py:2623} INFO - 0 downstream tasks scheduled from follow-on schedule check
[2022-11-29T06:31:17.542+0000] {taskinstance.py:1165} INFO - Dependencies all met for <TaskInstance: dag_try_oop.extractYtApiOperator scheduled__2022-11-28T03:00:00+00:00 [queued]>
[2022-11-29T06:31:17.946+0000] {taskinstance.py:1165} INFO - Dependencies all met for <TaskInstance: dag_try_oop.extractYtApiOperator scheduled__2022-11-28T03:00:00+00:00 [queued]>
[2022-11-29T06:31:17.952+0000] {taskinstance.py:1362} INFO - 
--------------------------------------------------------------------------------
[2022-11-29T06:31:17.957+0000] {taskinstance.py:1363} INFO - Starting attempt 1 of 2
[2022-11-29T06:31:17.968+0000] {taskinstance.py:1364} INFO - 
--------------------------------------------------------------------------------
[2022-11-29T06:31:18.837+0000] {taskinstance.py:1383} INFO - Executing <Task(extractYtApiOperator): extractYtApiOperator> on 2022-11-28 03:00:00+00:00
[2022-11-29T06:31:19.588+0000] {standard_task_runner.py:55} INFO - Started process 133 to run task
[2022-11-29T06:31:32.252+0000] {standard_task_runner.py:82} INFO - Running: ['***', 'tasks', 'run', 'dag_try_oop', 'extractYtApiOperator', 'scheduled__2022-11-28T03:00:00+00:00', '--job-id', '1075', '--raw', '--subdir', 'DAGS_FOLDER/dag_try_oop.py', '--cfg-path', '/tmp/tmp17dn_oty']
[2022-11-29T06:31:32.674+0000] {standard_task_runner.py:83} INFO - Job 1075: Subtask extractYtApiOperator
[2022-11-29T06:31:34.750+0000] {task_command.py:376} INFO - Running <TaskInstance: dag_try_oop.extractYtApiOperator scheduled__2022-11-28T03:00:00+00:00 [running]> on host 92b536e5af67
[2022-11-29T06:31:35.951+0000] {taskinstance.py:1592} INFO - Exporting the following env vars:
AIRFLOW_CTX_DAG_OWNER=***
AIRFLOW_CTX_DAG_ID=dag_try_oop
AIRFLOW_CTX_TASK_ID=extractYtApiOperator
AIRFLOW_CTX_EXECUTION_DATE=2022-11-28T03:00:00+00:00
AIRFLOW_CTX_TRY_NUMBER=1
AIRFLOW_CTX_DAG_RUN_ID=scheduled__2022-11-28T03:00:00+00:00
[2022-11-29T06:31:37.360+0000] {taskinstance.py:1851} ERROR - Task failed with exception
Traceback (most recent call last):
  File "/home/airflow/.local/lib/python3.7/site-packages/urllib3/connectionpool.py", line 710, in urlopen
    chunked=chunked,
  File "/home/airflow/.local/lib/python3.7/site-packages/urllib3/connectionpool.py", line 386, in _make_request
    self._validate_conn(conn)
  File "/home/airflow/.local/lib/python3.7/site-packages/urllib3/connectionpool.py", line 1042, in _validate_conn
    conn.connect()
  File "/home/airflow/.local/lib/python3.7/site-packages/urllib3/connection.py", line 424, in connect
    tls_in_tls=tls_in_tls,
  File "/home/airflow/.local/lib/python3.7/site-packages/urllib3/util/ssl_.py", line 450, in ssl_wrap_socket
    sock, context, tls_in_tls, server_hostname=server_hostname
  File "/home/airflow/.local/lib/python3.7/site-packages/urllib3/util/ssl_.py", line 493, in _ssl_wrap_socket_impl
    return ssl_context.wrap_socket(sock, server_hostname=server_hostname)
  File "/usr/local/lib/python3.7/ssl.py", line 423, in wrap_socket
    session=session
  File "/usr/local/lib/python3.7/ssl.py", line 870, in _create
    self.do_handshake()
  File "/usr/local/lib/python3.7/ssl.py", line 1139, in do_handshake
    self._sslobj.do_handshake()
ssl.SSLError: [SSL: UNSUPPORTED_PROTOCOL] unsupported protocol (_ssl.c:1091)

During handling of the above exception, another exception occurred:

Traceback (most recent call last):
  File "/home/airflow/.local/lib/python3.7/site-packages/requests/adapters.py", line 499, in send
    timeout=timeout,
  File "/home/airflow/.local/lib/python3.7/site-packages/urllib3/connectionpool.py", line 788, in urlopen
    method, url, error=e, _pool=self, _stacktrace=sys.exc_info()[2]
  File "/home/airflow/.local/lib/python3.7/site-packages/urllib3/util/retry.py", line 592, in increment
    raise MaxRetryError(_pool, url, error or ResponseError(cause))
urllib3.exceptions.MaxRetryError: HTTPSConnectionPool(host='www.googleapis.com', port=443): Max retries exceeded with url: /youtube/v3/videos?part=id,statistics,snippet&pageToken=CJYBEAA&chart=mostPopular&regionCode=ID&maxResults=50&key=AIzaSyAyC91r6h-lGuNp6hq8mhcO0fpkx4LrO-k (Caused by SSLError(SSLError(1, '[SSL: UNSUPPORTED_PROTOCOL] unsupported protocol (_ssl.c:1091)')))

During handling of the above exception, another exception occurred:

Traceback (most recent call last):
  File "/opt/airflow/plugins/operators/extractYtApiOperator.py", line 95, in execute
    get_data()
  File "/opt/airflow/plugins/operators/extractYtApiOperator.py", line 89, in get_data
    country_data = [",".join(header)] + get_pages(country_code)
  File "/opt/airflow/plugins/operators/extractYtApiOperator.py", line 69, in get_pages
    video_data_page = api_request(next_page_token, country_code)
  File "/opt/airflow/plugins/operators/extractYtApiOperator.py", line 29, in api_request
    request = requests.get(request_url)
  File "/home/airflow/.local/lib/python3.7/site-packages/requests/api.py", line 73, in get
    return request("get", url, params=params, **kwargs)
  File "/home/airflow/.local/lib/python3.7/site-packages/requests/api.py", line 59, in request
    return session.request(method=method, url=url, **kwargs)
  File "/home/airflow/.local/lib/python3.7/site-packages/requests/sessions.py", line 587, in request
    resp = self.send(prep, **send_kwargs)
  File "/home/airflow/.local/lib/python3.7/site-packages/requests/sessions.py", line 701, in send
    r = adapter.send(request, **kwargs)
  File "/home/airflow/.local/lib/python3.7/site-packages/requests/adapters.py", line 563, in send
    raise SSLError(e, request=request)
requests.exceptions.SSLError: HTTPSConnectionPool(host='www.googleapis.com', port=443): Max retries exceeded with url: /youtube/v3/videos?part=id,statistics,snippet&pageToken=CJYBEAA&chart=mostPopular&regionCode=ID&maxResults=50&key=AIzaSyAyC91r6h-lGuNp6hq8mhcO0fpkx4LrO-k (Caused by SSLError(SSLError(1, '[SSL: UNSUPPORTED_PROTOCOL] unsupported protocol (_ssl.c:1091)')))
[2022-11-29T06:31:37.551+0000] {taskinstance.py:1406} INFO - Marking task as UP_FOR_RETRY. dag_id=dag_try_oop, task_id=extractYtApiOperator, execution_date=20221128T030000, start_date=20221129T063117, end_date=20221129T063137
[2022-11-29T06:31:37.721+0000] {standard_task_runner.py:105} ERROR - Failed to execute job 1075 for task extractYtApiOperator (HTTPSConnectionPool(host='www.googleapis.com', port=443): Max retries exceeded with url: /youtube/v3/videos?part=id,statistics,snippet&pageToken=CJYBEAA&chart=mostPopular&regionCode=ID&maxResults=50&key=AIzaSyAyC91r6h-lGuNp6hq8mhcO0fpkx4LrO-k (Caused by SSLError(SSLError(1, '[SSL: UNSUPPORTED_PROTOCOL] unsupported protocol (_ssl.c:1091)'))); 133)
[2022-11-29T06:31:37.877+0000] {local_task_job.py:159} INFO - Task exited with return code 1
[2022-11-29T06:31:38.027+0000] {taskinstance.py:2623} INFO - 0 downstream tasks scheduled from follow-on schedule check
