[2022-11-28T16:29:40.984+0000] {taskinstance.py:1165} INFO - Dependencies all met for <TaskInstance: dag_try_oop.transformYtApiOperator scheduled__2022-11-27T21:00:00+00:00 [queued]>
[2022-11-28T16:29:41.147+0000] {taskinstance.py:1165} INFO - Dependencies all met for <TaskInstance: dag_try_oop.transformYtApiOperator scheduled__2022-11-27T21:00:00+00:00 [queued]>
[2022-11-28T16:29:41.158+0000] {taskinstance.py:1362} INFO - 
--------------------------------------------------------------------------------
[2022-11-28T16:29:41.166+0000] {taskinstance.py:1363} INFO - Starting attempt 2 of 2
[2022-11-28T16:29:41.172+0000] {taskinstance.py:1364} INFO - 
--------------------------------------------------------------------------------
[2022-11-28T16:29:41.437+0000] {taskinstance.py:1383} INFO - Executing <Task(transformYtApiOperator): transformYtApiOperator> on 2022-11-27 21:00:00+00:00
[2022-11-28T16:29:41.504+0000] {standard_task_runner.py:55} INFO - Started process 582 to run task
[2022-11-28T16:29:41.627+0000] {standard_task_runner.py:82} INFO - Running: ['***', 'tasks', 'run', 'dag_try_oop', 'transformYtApiOperator', 'scheduled__2022-11-27T21:00:00+00:00', '--job-id', '804', '--raw', '--subdir', 'DAGS_FOLDER/dag_try_oop.py', '--cfg-path', '/tmp/tmpam28klzn']
[2022-11-28T16:29:41.688+0000] {standard_task_runner.py:83} INFO - Job 804: Subtask transformYtApiOperator
[2022-11-28T16:29:43.069+0000] {task_command.py:376} INFO - Running <TaskInstance: dag_try_oop.transformYtApiOperator scheduled__2022-11-27T21:00:00+00:00 [running]> on host 1dd759b3e30c
[2022-11-28T16:29:47.734+0000] {taskinstance.py:1592} INFO - Exporting the following env vars:
AIRFLOW_CTX_DAG_OWNER=***
AIRFLOW_CTX_DAG_ID=dag_try_oop
AIRFLOW_CTX_TASK_ID=transformYtApiOperator
AIRFLOW_CTX_EXECUTION_DATE=2022-11-27T21:00:00+00:00
AIRFLOW_CTX_TRY_NUMBER=2
AIRFLOW_CTX_DAG_RUN_ID=scheduled__2022-11-27T21:00:00+00:00
[2022-11-28T16:29:47.783+0000] {taskinstance.py:1851} ERROR - Task failed with exception
Traceback (most recent call last):
  File "/opt/airflow/plugins/operators/transformYtApiOperator.py", line 30, in execute
    data = pd.read_csv('/opt/airflow/data/' + tablename + '.csv')
  File "/home/airflow/.local/lib/python3.7/site-packages/pandas/util/_decorators.py", line 311, in wrapper
    return func(*args, **kwargs)
  File "/home/airflow/.local/lib/python3.7/site-packages/pandas/io/parsers/readers.py", line 586, in read_csv
    return _read(filepath_or_buffer, kwds)
  File "/home/airflow/.local/lib/python3.7/site-packages/pandas/io/parsers/readers.py", line 488, in _read
    return parser.read(nrows)
  File "/home/airflow/.local/lib/python3.7/site-packages/pandas/io/parsers/readers.py", line 1047, in read
    index, columns, col_dict = self._engine.read(nrows)
  File "/home/airflow/.local/lib/python3.7/site-packages/pandas/io/parsers/c_parser_wrapper.py", line 224, in read
    chunks = self._reader.read_low_memory(nrows)
  File "pandas/_libs/parsers.pyx", line 801, in pandas._libs.parsers.TextReader.read_low_memory
  File "pandas/_libs/parsers.pyx", line 857, in pandas._libs.parsers.TextReader._read_rows
  File "pandas/_libs/parsers.pyx", line 843, in pandas._libs.parsers.TextReader._tokenize_rows
  File "pandas/_libs/parsers.pyx", line 1925, in pandas._libs.parsers.raise_parser_error
pandas.errors.ParserError: Error tokenizing data. C error: Expected 11 fields in line 82, saw 15

[2022-11-28T16:29:47.923+0000] {taskinstance.py:1406} INFO - Marking task as FAILED. dag_id=dag_try_oop, task_id=transformYtApiOperator, execution_date=20221127T210000, start_date=20221128T162940, end_date=20221128T162947
[2022-11-28T16:29:48.444+0000] {standard_task_runner.py:105} ERROR - Failed to execute job 804 for task transformYtApiOperator (Error tokenizing data. C error: Expected 11 fields in line 82, saw 15
; 582)
[2022-11-28T16:29:48.848+0000] {local_task_job.py:159} INFO - Task exited with return code 1
[2022-11-28T16:29:49.772+0000] {taskinstance.py:2623} INFO - 0 downstream tasks scheduled from follow-on schedule check
