[2022-11-27T11:47:01.819+0000] {taskinstance.py:1165} INFO - Dependencies all met for <TaskInstance: hello_world_dag.hello_world_task scheduled__2022-11-27T11:46:00+00:00 [queued]>
[2022-11-27T11:47:01.832+0000] {taskinstance.py:1165} INFO - Dependencies all met for <TaskInstance: hello_world_dag.hello_world_task scheduled__2022-11-27T11:46:00+00:00 [queued]>
[2022-11-27T11:47:01.832+0000] {taskinstance.py:1362} INFO - 
--------------------------------------------------------------------------------
[2022-11-27T11:47:01.833+0000] {taskinstance.py:1363} INFO - Starting attempt 1 of 4
[2022-11-27T11:47:01.833+0000] {taskinstance.py:1364} INFO - 
--------------------------------------------------------------------------------
[2022-11-27T11:47:01.850+0000] {taskinstance.py:1383} INFO - Executing <Task(PythonOperator): hello_world_task> on 2022-11-27 11:46:00+00:00
[2022-11-27T11:47:01.856+0000] {standard_task_runner.py:55} INFO - Started process 486 to run task
[2022-11-27T11:47:01.861+0000] {standard_task_runner.py:82} INFO - Running: ['***', 'tasks', 'run', 'hello_world_dag', 'hello_world_task', 'scheduled__2022-11-27T11:46:00+00:00', '--job-id', '316', '--raw', '--subdir', 'DAGS_FOLDER/dag_helloworld.py', '--cfg-path', '/tmp/tmpbn4_abna']
[2022-11-27T11:47:01.864+0000] {standard_task_runner.py:83} INFO - Job 316: Subtask hello_world_task
[2022-11-27T11:47:01.943+0000] {task_command.py:376} INFO - Running <TaskInstance: hello_world_dag.hello_world_task scheduled__2022-11-27T11:46:00+00:00 [running]> on host 8063ad561fea
[2022-11-27T11:47:02.042+0000] {taskinstance.py:1592} INFO - Exporting the following env vars:
AIRFLOW_CTX_DAG_OWNER=wiweka
AIRFLOW_CTX_DAG_ID=hello_world_dag
AIRFLOW_CTX_TASK_ID=hello_world_task
AIRFLOW_CTX_EXECUTION_DATE=2022-11-27T11:46:00+00:00
AIRFLOW_CTX_TRY_NUMBER=1
AIRFLOW_CTX_DAG_RUN_ID=scheduled__2022-11-27T11:46:00+00:00
[2022-11-27T11:47:12.053+0000] {taskinstance.py:1851} ERROR - Task failed with exception
Traceback (most recent call last):
  File "/usr/local/lib/python3.7/urllib/request.py", line 1350, in do_open
    encode_chunked=req.has_header('Transfer-encoding'))
  File "/usr/local/lib/python3.7/http/client.py", line 1281, in request
    self._send_request(method, url, body, headers, encode_chunked)
  File "/usr/local/lib/python3.7/http/client.py", line 1327, in _send_request
    self.endheaders(body, encode_chunked=encode_chunked)
  File "/usr/local/lib/python3.7/http/client.py", line 1276, in endheaders
    self._send_output(message_body, encode_chunked=encode_chunked)
  File "/usr/local/lib/python3.7/http/client.py", line 1036, in _send_output
    self.send(msg)
  File "/usr/local/lib/python3.7/http/client.py", line 976, in send
    self.connect()
  File "/usr/local/lib/python3.7/http/client.py", line 1443, in connect
    super().connect()
  File "/usr/local/lib/python3.7/http/client.py", line 948, in connect
    (self.host,self.port), self.timeout, self.source_address)
  File "/usr/local/lib/python3.7/socket.py", line 707, in create_connection
    for res in getaddrinfo(host, port, 0, SOCK_STREAM):
  File "/usr/local/lib/python3.7/socket.py", line 752, in getaddrinfo
    for res in _socket.getaddrinfo(host, port, family, type, proto, flags):
socket.gaierror: [Errno -3] Temporary failure in name resolution

During handling of the above exception, another exception occurred:

Traceback (most recent call last):
  File "/home/airflow/.local/lib/python3.7/site-packages/airflow/operators/python.py", line 175, in execute
    return_value = self.execute_callable()
  File "/home/airflow/.local/lib/python3.7/site-packages/airflow/operators/python.py", line 193, in execute_callable
    return self.python_callable(*self.op_args, **self.op_kwargs)
  File "/opt/airflow/dags/dag_helloworld.py", line 36, in print_hello
    response = urllib.request.urlopen(url)
  File "/usr/local/lib/python3.7/urllib/request.py", line 222, in urlopen
    return opener.open(url, data, timeout)
  File "/usr/local/lib/python3.7/urllib/request.py", line 525, in open
    response = self._open(req, data)
  File "/usr/local/lib/python3.7/urllib/request.py", line 543, in _open
    '_open', req)
  File "/usr/local/lib/python3.7/urllib/request.py", line 503, in _call_chain
    result = func(*args)
  File "/usr/local/lib/python3.7/urllib/request.py", line 1393, in https_open
    context=self._context, check_hostname=self._check_hostname)
  File "/usr/local/lib/python3.7/urllib/request.py", line 1352, in do_open
    raise URLError(err)
urllib.error.URLError: <urlopen error [Errno -3] Temporary failure in name resolution>
[2022-11-27T11:47:12.070+0000] {taskinstance.py:1406} INFO - Marking task as UP_FOR_RETRY. dag_id=hello_world_dag, task_id=hello_world_task, execution_date=20221127T114600, start_date=20221127T114701, end_date=20221127T114712
[2022-11-27T11:47:12.100+0000] {standard_task_runner.py:105} ERROR - Failed to execute job 316 for task hello_world_task (<urlopen error [Errno -3] Temporary failure in name resolution>; 486)
[2022-11-27T11:47:12.148+0000] {local_task_job.py:159} INFO - Task exited with return code 1
[2022-11-27T11:47:12.178+0000] {taskinstance.py:2623} INFO - 0 downstream tasks scheduled from follow-on schedule check
