[2022-11-27T11:57:45.608+0000] {taskinstance.py:1165} INFO - Dependencies all met for <TaskInstance: using_pandas_demo.getDataToLocal manual__2022-11-27T11:51:32.665669+00:00 [queued]>
[2022-11-27T11:57:45.626+0000] {taskinstance.py:1165} INFO - Dependencies all met for <TaskInstance: using_pandas_demo.getDataToLocal manual__2022-11-27T11:51:32.665669+00:00 [queued]>
[2022-11-27T11:57:45.626+0000] {taskinstance.py:1362} INFO - 
--------------------------------------------------------------------------------
[2022-11-27T11:57:45.626+0000] {taskinstance.py:1363} INFO - Starting attempt 2 of 2
[2022-11-27T11:57:45.631+0000] {taskinstance.py:1364} INFO - 
--------------------------------------------------------------------------------
[2022-11-27T11:57:45.660+0000] {taskinstance.py:1383} INFO - Executing <Task(PythonOperator): getDataToLocal> on 2022-11-27 11:51:32.665669+00:00
[2022-11-27T11:57:45.665+0000] {standard_task_runner.py:55} INFO - Started process 996 to run task
[2022-11-27T11:57:45.678+0000] {standard_task_runner.py:82} INFO - Running: ['***', 'tasks', 'run', 'using_pandas_demo', 'getDataToLocal', 'manual__2022-11-27T11:51:32.665669+00:00', '--job-id', '323', '--raw', '--subdir', 'DAGS_FOLDER/dag_pandas_demo.py', '--cfg-path', '/tmp/tmphj7t8uev']
[2022-11-27T11:57:45.691+0000] {standard_task_runner.py:83} INFO - Job 323: Subtask getDataToLocal
[2022-11-27T11:57:45.952+0000] {task_command.py:376} INFO - Running <TaskInstance: using_pandas_demo.getDataToLocal manual__2022-11-27T11:51:32.665669+00:00 [running]> on host 8063ad561fea
[2022-11-27T11:57:46.070+0000] {taskinstance.py:1592} INFO - Exporting the following env vars:
AIRFLOW_CTX_DAG_OWNER=***
AIRFLOW_CTX_DAG_ID=using_pandas_demo
AIRFLOW_CTX_TASK_ID=getDataToLocal
AIRFLOW_CTX_EXECUTION_DATE=2022-11-27T11:51:32.665669+00:00
AIRFLOW_CTX_TRY_NUMBER=2
AIRFLOW_CTX_DAG_RUN_ID=manual__2022-11-27T11:51:32.665669+00:00
[2022-11-27T11:57:50.376+0000] {taskinstance.py:1851} ERROR - Task failed with exception
Traceback (most recent call last):
  File "/home/airflow/.local/lib/python3.7/site-packages/airflow/operators/python.py", line 175, in execute
    return_value = self.execute_callable()
  File "/home/airflow/.local/lib/python3.7/site-packages/airflow/operators/python.py", line 193, in execute_callable
    return self.python_callable(*self.op_args, **self.op_kwargs)
  File "/opt/airflow/dags/dag_pandas_demo.py", line 36, in getDataToLocal
    df.to_csv("/home/wiweka/Downloads/drivers.csv", sep=',' ,escapechar='\\', quoting=csv.QUOTE_ALL, encoding='utf-8' )
NameError: name 'csv' is not defined
[2022-11-27T11:57:50.384+0000] {taskinstance.py:1406} INFO - Marking task as FAILED. dag_id=using_pandas_demo, task_id=getDataToLocal, execution_date=20221127T115132, start_date=20221127T115745, end_date=20221127T115750
[2022-11-27T11:57:50.397+0000] {standard_task_runner.py:105} ERROR - Failed to execute job 323 for task getDataToLocal (name 'csv' is not defined; 996)
[2022-11-27T11:57:50.435+0000] {local_task_job.py:159} INFO - Task exited with return code 1
[2022-11-27T11:57:50.461+0000] {taskinstance.py:2623} INFO - 0 downstream tasks scheduled from follow-on schedule check
