[2022-11-27T12:34:34.107+0000] {taskinstance.py:1165} INFO - Dependencies all met for <TaskInstance: using_pandas_demo.creatableLoad manual__2022-11-27T12:29:08.893369+00:00 [queued]>
[2022-11-27T12:34:34.116+0000] {taskinstance.py:1165} INFO - Dependencies all met for <TaskInstance: using_pandas_demo.creatableLoad manual__2022-11-27T12:29:08.893369+00:00 [queued]>
[2022-11-27T12:34:34.117+0000] {taskinstance.py:1362} INFO - 
--------------------------------------------------------------------------------
[2022-11-27T12:34:34.117+0000] {taskinstance.py:1363} INFO - Starting attempt 2 of 2
[2022-11-27T12:34:34.117+0000] {taskinstance.py:1364} INFO - 
--------------------------------------------------------------------------------
[2022-11-27T12:34:34.132+0000] {taskinstance.py:1383} INFO - Executing <Task(PythonOperator): creatableLoad> on 2022-11-27 12:29:08.893369+00:00
[2022-11-27T12:34:34.138+0000] {standard_task_runner.py:55} INFO - Started process 868 to run task
[2022-11-27T12:34:34.145+0000] {standard_task_runner.py:82} INFO - Running: ['***', 'tasks', 'run', 'using_pandas_demo', 'creatableLoad', 'manual__2022-11-27T12:29:08.893369+00:00', '--job-id', '347', '--raw', '--subdir', 'DAGS_FOLDER/dag_pandas_demo.py', '--cfg-path', '/tmp/tmppn8r6mxp']
[2022-11-27T12:34:34.147+0000] {standard_task_runner.py:83} INFO - Job 347: Subtask creatableLoad
[2022-11-27T12:34:34.209+0000] {task_command.py:376} INFO - Running <TaskInstance: using_pandas_demo.creatableLoad manual__2022-11-27T12:29:08.893369+00:00 [running]> on host 1977dd9b5152
[2022-11-27T12:34:34.267+0000] {taskinstance.py:1592} INFO - Exporting the following env vars:
AIRFLOW_CTX_DAG_OWNER=***
AIRFLOW_CTX_DAG_ID=using_pandas_demo
AIRFLOW_CTX_TASK_ID=creatableLoad
AIRFLOW_CTX_EXECUTION_DATE=2022-11-27T12:29:08.893369+00:00
AIRFLOW_CTX_TRY_NUMBER=2
AIRFLOW_CTX_DAG_RUN_ID=manual__2022-11-27T12:29:08.893369+00:00
[2022-11-27T12:34:34.268+0000] {logging_mixin.py:137} INFO - connection to server at "localhost" (127.0.0.1), port 5432 failed: Connection refused
	Is the server running on that host and accepting TCP/IP connections?
connection to server at "localhost" (::1), port 5432 failed: Cannot assign requested address
	Is the server running on that host and accepting TCP/IP connections?
[2022-11-27T12:34:34.268+0000] {taskinstance.py:1851} ERROR - Task failed with exception
Traceback (most recent call last):
  File "/home/airflow/.local/lib/python3.7/site-packages/airflow/operators/python.py", line 175, in execute
    return_value = self.execute_callable()
  File "/home/airflow/.local/lib/python3.7/site-packages/airflow/operators/python.py", line 193, in execute_callable
    return self.python_callable(*self.op_args, **self.op_kwargs)
  File "/opt/airflow/dags/dag_pandas_demo.py", line 49, in creatableLoad
    cursor = dbconnect.cursor()
UnboundLocalError: local variable 'dbconnect' referenced before assignment
[2022-11-27T12:34:34.275+0000] {taskinstance.py:1406} INFO - Marking task as FAILED. dag_id=using_pandas_demo, task_id=creatableLoad, execution_date=20221127T122908, start_date=20221127T123434, end_date=20221127T123434
[2022-11-27T12:34:34.285+0000] {standard_task_runner.py:105} ERROR - Failed to execute job 347 for task creatableLoad (local variable 'dbconnect' referenced before assignment; 868)
[2022-11-27T12:34:34.313+0000] {local_task_job.py:159} INFO - Task exited with return code 1
[2022-11-27T12:34:34.328+0000] {taskinstance.py:2623} INFO - 0 downstream tasks scheduled from follow-on schedule check
