[2022-11-28T03:48:40.877+0000] {taskinstance.py:1165} INFO - Dependencies all met for <TaskInstance: dag_youtube_api.creatableLoad manual__2022-11-28T03:43:36.244638+00:00 [queued]>
[2022-11-28T03:48:40.892+0000] {taskinstance.py:1165} INFO - Dependencies all met for <TaskInstance: dag_youtube_api.creatableLoad manual__2022-11-28T03:43:36.244638+00:00 [queued]>
[2022-11-28T03:48:40.893+0000] {taskinstance.py:1362} INFO - 
--------------------------------------------------------------------------------
[2022-11-28T03:48:40.893+0000] {taskinstance.py:1363} INFO - Starting attempt 2 of 2
[2022-11-28T03:48:40.893+0000] {taskinstance.py:1364} INFO - 
--------------------------------------------------------------------------------
[2022-11-28T03:48:40.910+0000] {taskinstance.py:1383} INFO - Executing <Task(PythonOperator): creatableLoad> on 2022-11-28 03:43:36.244638+00:00
[2022-11-28T03:48:40.918+0000] {standard_task_runner.py:55} INFO - Started process 559 to run task
[2022-11-28T03:48:40.926+0000] {standard_task_runner.py:82} INFO - Running: ['***', 'tasks', 'run', 'dag_youtube_api', 'creatableLoad', 'manual__2022-11-28T03:43:36.244638+00:00', '--job-id', '434', '--raw', '--subdir', 'DAGS_FOLDER/dag_youtube_api.py', '--cfg-path', '/tmp/tmpbkqabq7g']
[2022-11-28T03:48:40.931+0000] {standard_task_runner.py:83} INFO - Job 434: Subtask creatableLoad
[2022-11-28T03:48:41.020+0000] {task_command.py:376} INFO - Running <TaskInstance: dag_youtube_api.creatableLoad manual__2022-11-28T03:43:36.244638+00:00 [running]> on host 1977dd9b5152
[2022-11-28T03:48:41.126+0000] {taskinstance.py:1592} INFO - Exporting the following env vars:
AIRFLOW_CTX_DAG_OWNER=***
AIRFLOW_CTX_DAG_ID=dag_youtube_api
AIRFLOW_CTX_TASK_ID=creatableLoad
AIRFLOW_CTX_EXECUTION_DATE=2022-11-28T03:43:36.244638+00:00
AIRFLOW_CTX_TRY_NUMBER=2
AIRFLOW_CTX_DAG_RUN_ID=manual__2022-11-28T03:43:36.244638+00:00
[2022-11-28T03:48:41.157+0000] {taskinstance.py:1851} ERROR - Task failed with exception
Traceback (most recent call last):
  File "/home/airflow/.local/lib/python3.7/site-packages/airflow/operators/python.py", line 175, in execute
    return_value = self.execute_callable()
  File "/home/airflow/.local/lib/python3.7/site-packages/airflow/operators/python.py", line 193, in execute_callable
    return self.python_callable(*self.op_args, **self.op_kwargs)
  File "/opt/airflow/dags/dag_youtube_api.py", line 178, in creatableLoad
    row.split(",")[10])
psycopg2.errors.StringDataRightTruncation: value too long for type character varying(100)

[2022-11-28T03:48:41.176+0000] {taskinstance.py:1406} INFO - Marking task as FAILED. dag_id=dag_youtube_api, task_id=creatableLoad, execution_date=20221128T034336, start_date=20221128T034840, end_date=20221128T034841
[2022-11-28T03:48:41.197+0000] {standard_task_runner.py:105} ERROR - Failed to execute job 434 for task creatableLoad (value too long for type character varying(100)
; 559)
[2022-11-28T03:48:41.258+0000] {local_task_job.py:159} INFO - Task exited with return code 1
[2022-11-28T03:48:41.280+0000] {taskinstance.py:2623} INFO - 0 downstream tasks scheduled from follow-on schedule check
