[2022-11-27T12:45:56.350+0000] {taskinstance.py:1165} INFO - Dependencies all met for <TaskInstance: using_pandas_demo.getDataToLocal manual__2022-11-27T12:45:54.585227+00:00 [queued]>
[2022-11-27T12:45:56.366+0000] {taskinstance.py:1165} INFO - Dependencies all met for <TaskInstance: using_pandas_demo.getDataToLocal manual__2022-11-27T12:45:54.585227+00:00 [queued]>
[2022-11-27T12:45:56.366+0000] {taskinstance.py:1362} INFO - 
--------------------------------------------------------------------------------
[2022-11-27T12:45:56.367+0000] {taskinstance.py:1363} INFO - Starting attempt 1 of 2
[2022-11-27T12:45:56.367+0000] {taskinstance.py:1364} INFO - 
--------------------------------------------------------------------------------
[2022-11-27T12:45:56.386+0000] {taskinstance.py:1383} INFO - Executing <Task(PythonOperator): getDataToLocal> on 2022-11-27 12:45:54.585227+00:00
[2022-11-27T12:45:56.395+0000] {standard_task_runner.py:55} INFO - Started process 1417 to run task
[2022-11-27T12:45:56.404+0000] {standard_task_runner.py:82} INFO - Running: ['***', 'tasks', 'run', 'using_pandas_demo', 'getDataToLocal', 'manual__2022-11-27T12:45:54.585227+00:00', '--job-id', '352', '--raw', '--subdir', 'DAGS_FOLDER/dag_pandas_demo.py', '--cfg-path', '/tmp/tmpdvxgqhmf']
[2022-11-27T12:45:56.410+0000] {standard_task_runner.py:83} INFO - Job 352: Subtask getDataToLocal
[2022-11-27T12:45:56.527+0000] {task_command.py:376} INFO - Running <TaskInstance: using_pandas_demo.getDataToLocal manual__2022-11-27T12:45:54.585227+00:00 [running]> on host 1977dd9b5152
[2022-11-27T12:45:56.636+0000] {taskinstance.py:1592} INFO - Exporting the following env vars:
AIRFLOW_CTX_DAG_OWNER=***
AIRFLOW_CTX_DAG_ID=using_pandas_demo
AIRFLOW_CTX_TASK_ID=getDataToLocal
AIRFLOW_CTX_EXECUTION_DATE=2022-11-27T12:45:54.585227+00:00
AIRFLOW_CTX_TRY_NUMBER=1
AIRFLOW_CTX_DAG_RUN_ID=manual__2022-11-27T12:45:54.585227+00:00
[2022-11-27T12:46:06.655+0000] {taskinstance.py:1851} ERROR - Task failed with exception
Traceback (most recent call last):
  File "/home/airflow/.local/lib/python3.7/site-packages/urllib3/connection.py", line 175, in _new_conn
    (self._dns_host, self.port), self.timeout, **extra_kw
  File "/home/airflow/.local/lib/python3.7/site-packages/urllib3/util/connection.py", line 72, in create_connection
    for res in socket.getaddrinfo(host, port, family, socket.SOCK_STREAM):
  File "/usr/local/lib/python3.7/socket.py", line 752, in getaddrinfo
    for res in _socket.getaddrinfo(host, port, family, type, proto, flags):
socket.gaierror: [Errno -3] Temporary failure in name resolution

During handling of the above exception, another exception occurred:

Traceback (most recent call last):
  File "/home/airflow/.local/lib/python3.7/site-packages/urllib3/connectionpool.py", line 710, in urlopen
    chunked=chunked,
  File "/home/airflow/.local/lib/python3.7/site-packages/urllib3/connectionpool.py", line 386, in _make_request
    self._validate_conn(conn)
  File "/home/airflow/.local/lib/python3.7/site-packages/urllib3/connectionpool.py", line 1042, in _validate_conn
    conn.connect()
  File "/home/airflow/.local/lib/python3.7/site-packages/urllib3/connection.py", line 358, in connect
    self.sock = conn = self._new_conn()
  File "/home/airflow/.local/lib/python3.7/site-packages/urllib3/connection.py", line 187, in _new_conn
    self, "Failed to establish a new connection: %s" % e
urllib3.exceptions.NewConnectionError: <urllib3.connection.HTTPSConnection object at 0x7f62121c8550>: Failed to establish a new connection: [Errno -3] Temporary failure in name resolution

During handling of the above exception, another exception occurred:

Traceback (most recent call last):
  File "/home/airflow/.local/lib/python3.7/site-packages/requests/adapters.py", line 499, in send
    timeout=timeout,
  File "/home/airflow/.local/lib/python3.7/site-packages/urllib3/connectionpool.py", line 788, in urlopen
    method, url, error=e, _pool=self, _stacktrace=sys.exc_info()[2]
  File "/home/airflow/.local/lib/python3.7/site-packages/urllib3/util/retry.py", line 592, in increment
    raise MaxRetryError(_pool, url, error or ResponseError(cause))
urllib3.exceptions.MaxRetryError: HTTPSConnectionPool(host='data.cityofnewyork.us', port=443): Max retries exceeded with url: /resource/4tqt-y424.json (Caused by NewConnectionError('<urllib3.connection.HTTPSConnection object at 0x7f62121c8550>: Failed to establish a new connection: [Errno -3] Temporary failure in name resolution'))

During handling of the above exception, another exception occurred:

Traceback (most recent call last):
  File "/home/airflow/.local/lib/python3.7/site-packages/airflow/operators/python.py", line 175, in execute
    return_value = self.execute_callable()
  File "/home/airflow/.local/lib/python3.7/site-packages/airflow/operators/python.py", line 193, in execute_callable
    return self.python_callable(*self.op_args, **self.op_kwargs)
  File "/opt/airflow/dags/dag_pandas_demo.py", line 32, in getDataToLocal
    response = requests.get(url)
  File "/home/airflow/.local/lib/python3.7/site-packages/requests/api.py", line 73, in get
    return request("get", url, params=params, **kwargs)
  File "/home/airflow/.local/lib/python3.7/site-packages/requests/api.py", line 59, in request
    return session.request(method=method, url=url, **kwargs)
  File "/home/airflow/.local/lib/python3.7/site-packages/requests/sessions.py", line 587, in request
    resp = self.send(prep, **send_kwargs)
  File "/home/airflow/.local/lib/python3.7/site-packages/requests/sessions.py", line 701, in send
    r = adapter.send(request, **kwargs)
  File "/home/airflow/.local/lib/python3.7/site-packages/requests/adapters.py", line 565, in send
    raise ConnectionError(e, request=request)
requests.exceptions.ConnectionError: HTTPSConnectionPool(host='data.cityofnewyork.us', port=443): Max retries exceeded with url: /resource/4tqt-y424.json (Caused by NewConnectionError('<urllib3.connection.HTTPSConnection object at 0x7f62121c8550>: Failed to establish a new connection: [Errno -3] Temporary failure in name resolution'))
[2022-11-27T12:46:06.673+0000] {taskinstance.py:1406} INFO - Marking task as UP_FOR_RETRY. dag_id=using_pandas_demo, task_id=getDataToLocal, execution_date=20221127T124554, start_date=20221127T124556, end_date=20221127T124606
[2022-11-27T12:46:06.696+0000] {standard_task_runner.py:105} ERROR - Failed to execute job 352 for task getDataToLocal (HTTPSConnectionPool(host='data.cityofnewyork.us', port=443): Max retries exceeded with url: /resource/4tqt-y424.json (Caused by NewConnectionError('<urllib3.connection.HTTPSConnection object at 0x7f62121c8550>: Failed to establish a new connection: [Errno -3] Temporary failure in name resolution')); 1417)
[2022-11-27T12:46:06.726+0000] {local_task_job.py:159} INFO - Task exited with return code 1
[2022-11-27T12:46:06.776+0000] {taskinstance.py:2623} INFO - 0 downstream tasks scheduled from follow-on schedule check
