[2022-11-27T11:51:25.648+0000] {taskinstance.py:1165} INFO - Dependencies all met for <TaskInstance: using_pandas_demo.getDataToLocal scheduled__2022-11-26T00:00:00+00:00 [queued]>
[2022-11-27T11:51:25.690+0000] {taskinstance.py:1165} INFO - Dependencies all met for <TaskInstance: using_pandas_demo.getDataToLocal scheduled__2022-11-26T00:00:00+00:00 [queued]>
[2022-11-27T11:51:25.691+0000] {taskinstance.py:1362} INFO - 
--------------------------------------------------------------------------------
[2022-11-27T11:51:25.691+0000] {taskinstance.py:1363} INFO - Starting attempt 1 of 2
[2022-11-27T11:51:25.692+0000] {taskinstance.py:1364} INFO - 
--------------------------------------------------------------------------------
[2022-11-27T11:51:25.715+0000] {taskinstance.py:1383} INFO - Executing <Task(PythonOperator): getDataToLocal> on 2022-11-26 00:00:00+00:00
[2022-11-27T11:51:25.725+0000] {standard_task_runner.py:55} INFO - Started process 710 to run task
[2022-11-27T11:51:25.736+0000] {standard_task_runner.py:82} INFO - Running: ['***', 'tasks', 'run', 'using_pandas_demo', 'getDataToLocal', 'scheduled__2022-11-26T00:00:00+00:00', '--job-id', '321', '--raw', '--subdir', 'DAGS_FOLDER/dag_pandas_demo.py', '--cfg-path', '/tmp/tmprxcb4yow']
[2022-11-27T11:51:25.737+0000] {standard_task_runner.py:83} INFO - Job 321: Subtask getDataToLocal
[2022-11-27T11:51:25.856+0000] {task_command.py:376} INFO - Running <TaskInstance: using_pandas_demo.getDataToLocal scheduled__2022-11-26T00:00:00+00:00 [running]> on host 8063ad561fea
[2022-11-27T11:51:26.003+0000] {taskinstance.py:1592} INFO - Exporting the following env vars:
AIRFLOW_CTX_DAG_OWNER=***
AIRFLOW_CTX_DAG_ID=using_pandas_demo
AIRFLOW_CTX_TASK_ID=getDataToLocal
AIRFLOW_CTX_EXECUTION_DATE=2022-11-26T00:00:00+00:00
AIRFLOW_CTX_TRY_NUMBER=1
AIRFLOW_CTX_DAG_RUN_ID=scheduled__2022-11-26T00:00:00+00:00
[2022-11-27T11:51:32.173+0000] {taskinstance.py:1851} ERROR - Task failed with exception
Traceback (most recent call last):
  File "/home/airflow/.local/lib/python3.7/site-packages/airflow/operators/python.py", line 175, in execute
    return_value = self.execute_callable()
  File "/home/airflow/.local/lib/python3.7/site-packages/airflow/operators/python.py", line 193, in execute_callable
    return self.python_callable(*self.op_args, **self.op_kwargs)
  File "/opt/airflow/dags/dag_pandas_demo.py", line 31, in getDataToLocal
    df = pd.DataFrame(json.loads(response.content))
NameError: name 'pd' is not defined
[2022-11-27T11:51:32.184+0000] {taskinstance.py:1406} INFO - Marking task as UP_FOR_RETRY. dag_id=using_pandas_demo, task_id=getDataToLocal, execution_date=20221126T000000, start_date=20221127T115125, end_date=20221127T115132
[2022-11-27T11:51:32.200+0000] {standard_task_runner.py:105} ERROR - Failed to execute job 321 for task getDataToLocal (name 'pd' is not defined; 710)
[2022-11-27T11:51:32.230+0000] {local_task_job.py:159} INFO - Task exited with return code 1
[2022-11-27T11:51:32.260+0000] {taskinstance.py:2623} INFO - 0 downstream tasks scheduled from follow-on schedule check
