[2022-11-27T16:32:25.126+0000] {taskinstance.py:1165} INFO - Dependencies all met for <TaskInstance: dag_youtube_api.creatableLoad manual__2022-11-27T16:32:17.583387+00:00 [queued]>
[2022-11-27T16:32:25.175+0000] {taskinstance.py:1165} INFO - Dependencies all met for <TaskInstance: dag_youtube_api.creatableLoad manual__2022-11-27T16:32:17.583387+00:00 [queued]>
[2022-11-27T16:32:25.176+0000] {taskinstance.py:1362} INFO - 
--------------------------------------------------------------------------------
[2022-11-27T16:32:25.177+0000] {taskinstance.py:1363} INFO - Starting attempt 1 of 2
[2022-11-27T16:32:25.177+0000] {taskinstance.py:1364} INFO - 
--------------------------------------------------------------------------------
[2022-11-27T16:32:25.265+0000] {taskinstance.py:1383} INFO - Executing <Task(PythonOperator): creatableLoad> on 2022-11-27 16:32:17.583387+00:00
[2022-11-27T16:32:25.298+0000] {standard_task_runner.py:55} INFO - Started process 9889 to run task
[2022-11-27T16:32:25.319+0000] {standard_task_runner.py:82} INFO - Running: ['***', 'tasks', 'run', 'dag_youtube_api', 'creatableLoad', 'manual__2022-11-27T16:32:17.583387+00:00', '--job-id', '380', '--raw', '--subdir', 'DAGS_FOLDER/dag_youtube_api.py', '--cfg-path', '/tmp/tmp40ehp88h']
[2022-11-27T16:32:25.330+0000] {standard_task_runner.py:83} INFO - Job 380: Subtask creatableLoad
[2022-11-27T16:32:25.624+0000] {task_command.py:376} INFO - Running <TaskInstance: dag_youtube_api.creatableLoad manual__2022-11-27T16:32:17.583387+00:00 [running]> on host 1977dd9b5152
[2022-11-27T16:32:26.365+0000] {taskinstance.py:1592} INFO - Exporting the following env vars:
AIRFLOW_CTX_DAG_OWNER=***
AIRFLOW_CTX_DAG_ID=dag_youtube_api
AIRFLOW_CTX_TASK_ID=creatableLoad
AIRFLOW_CTX_EXECUTION_DATE=2022-11-27T16:32:17.583387+00:00
AIRFLOW_CTX_TRY_NUMBER=1
AIRFLOW_CTX_DAG_RUN_ID=manual__2022-11-27T16:32:17.583387+00:00
[2022-11-27T16:32:26.470+0000] {taskinstance.py:1851} ERROR - Task failed with exception
Traceback (most recent call last):
  File "/home/airflow/.local/lib/python3.7/site-packages/airflow/operators/python.py", line 175, in execute
    return_value = self.execute_callable()
  File "/home/airflow/.local/lib/python3.7/site-packages/airflow/operators/python.py", line 193, in execute_callable
    return self.python_callable(*self.op_args, **self.op_kwargs)
  File "/opt/airflow/dags/dag_youtube_api.py", line 171, in creatableLoad
    row.split(",")[10])
psycopg2.errors.StringDataRightTruncation: value too long for type character varying(50)

[2022-11-27T16:32:26.563+0000] {taskinstance.py:1406} INFO - Marking task as UP_FOR_RETRY. dag_id=dag_youtube_api, task_id=creatableLoad, execution_date=20221127T163217, start_date=20221127T163225, end_date=20221127T163226
[2022-11-27T16:32:26.670+0000] {standard_task_runner.py:105} ERROR - Failed to execute job 380 for task creatableLoad (value too long for type character varying(50)
; 9889)
[2022-11-27T16:32:26.751+0000] {local_task_job.py:159} INFO - Task exited with return code 1
[2022-11-27T16:32:27.034+0000] {taskinstance.py:2623} INFO - 0 downstream tasks scheduled from follow-on schedule check
