[2022-11-28T04:12:59.216+0000] {taskinstance.py:1165} INFO - Dependencies all met for <TaskInstance: dag_youtube_api.creatableLoad manual__2022-11-28T04:12:48.821741+00:00 [queued]>
[2022-11-28T04:12:59.294+0000] {taskinstance.py:1165} INFO - Dependencies all met for <TaskInstance: dag_youtube_api.creatableLoad manual__2022-11-28T04:12:48.821741+00:00 [queued]>
[2022-11-28T04:12:59.299+0000] {taskinstance.py:1362} INFO - 
--------------------------------------------------------------------------------
[2022-11-28T04:12:59.301+0000] {taskinstance.py:1363} INFO - Starting attempt 1 of 2
[2022-11-28T04:12:59.302+0000] {taskinstance.py:1364} INFO - 
--------------------------------------------------------------------------------
[2022-11-28T04:12:59.562+0000] {taskinstance.py:1383} INFO - Executing <Task(PythonOperator): creatableLoad> on 2022-11-28 04:12:48.821741+00:00
[2022-11-28T04:12:59.645+0000] {standard_task_runner.py:55} INFO - Started process 1689 to run task
[2022-11-28T04:12:59.715+0000] {standard_task_runner.py:82} INFO - Running: ['***', 'tasks', 'run', 'dag_youtube_api', 'creatableLoad', 'manual__2022-11-28T04:12:48.821741+00:00', '--job-id', '443', '--raw', '--subdir', 'DAGS_FOLDER/dag_youtube_api.py', '--cfg-path', '/tmp/tmpm_54qvlv']
[2022-11-28T04:12:59.740+0000] {standard_task_runner.py:83} INFO - Job 443: Subtask creatableLoad
[2022-11-28T04:13:00.429+0000] {task_command.py:376} INFO - Running <TaskInstance: dag_youtube_api.creatableLoad manual__2022-11-28T04:12:48.821741+00:00 [running]> on host 1977dd9b5152
[2022-11-28T04:13:00.750+0000] {taskinstance.py:1592} INFO - Exporting the following env vars:
AIRFLOW_CTX_DAG_OWNER=***
AIRFLOW_CTX_DAG_ID=dag_youtube_api
AIRFLOW_CTX_TASK_ID=creatableLoad
AIRFLOW_CTX_EXECUTION_DATE=2022-11-28T04:12:48.821741+00:00
AIRFLOW_CTX_TRY_NUMBER=1
AIRFLOW_CTX_DAG_RUN_ID=manual__2022-11-28T04:12:48.821741+00:00
[2022-11-28T04:13:00.802+0000] {taskinstance.py:1851} ERROR - Task failed with exception
Traceback (most recent call last):
  File "/home/airflow/.local/lib/python3.7/site-packages/airflow/operators/python.py", line 175, in execute
    return_value = self.execute_callable()
  File "/home/airflow/.local/lib/python3.7/site-packages/airflow/operators/python.py", line 193, in execute_callable
    return self.python_callable(*self.op_args, **self.op_kwargs)
  File "/opt/airflow/dags/dag_youtube_api.py", line 192, in creatableLoad
    row.split(",")[10])
psycopg2.errors.SyntaxError: syntax error at or near "academy"
LINE 3: ...enre:etc|format:highlight|type:broadcast|series:d'academy 5|...
                                                             ^

[2022-11-28T04:13:00.853+0000] {taskinstance.py:1406} INFO - Marking task as UP_FOR_RETRY. dag_id=dag_youtube_api, task_id=creatableLoad, execution_date=20221128T041248, start_date=20221128T041259, end_date=20221128T041300
[2022-11-28T04:13:00.921+0000] {standard_task_runner.py:105} ERROR - Failed to execute job 443 for task creatableLoad (syntax error at or near "academy"
LINE 3: ...enre:etc|format:highlight|type:broadcast|series:d'academy 5|...
                                                             ^
; 1689)
[2022-11-28T04:13:01.015+0000] {local_task_job.py:159} INFO - Task exited with return code 1
[2022-11-28T04:13:01.093+0000] {taskinstance.py:2623} INFO - 0 downstream tasks scheduled from follow-on schedule check
