[2022-11-27T12:41:23.662+0000] {taskinstance.py:1165} INFO - Dependencies all met for <TaskInstance: using_pandas_demo.creatableLoad manual__2022-11-27T12:41:11.917012+00:00 [queued]>
[2022-11-27T12:41:23.675+0000] {taskinstance.py:1165} INFO - Dependencies all met for <TaskInstance: using_pandas_demo.creatableLoad manual__2022-11-27T12:41:11.917012+00:00 [queued]>
[2022-11-27T12:41:23.676+0000] {taskinstance.py:1362} INFO - 
--------------------------------------------------------------------------------
[2022-11-27T12:41:23.676+0000] {taskinstance.py:1363} INFO - Starting attempt 1 of 2
[2022-11-27T12:41:23.676+0000] {taskinstance.py:1364} INFO - 
--------------------------------------------------------------------------------
[2022-11-27T12:41:23.696+0000] {taskinstance.py:1383} INFO - Executing <Task(PythonOperator): creatableLoad> on 2022-11-27 12:41:11.917012+00:00
[2022-11-27T12:41:23.703+0000] {standard_task_runner.py:55} INFO - Started process 1207 to run task
[2022-11-27T12:41:23.709+0000] {standard_task_runner.py:82} INFO - Running: ['***', 'tasks', 'run', 'using_pandas_demo', 'creatableLoad', 'manual__2022-11-27T12:41:11.917012+00:00', '--job-id', '351', '--raw', '--subdir', 'DAGS_FOLDER/dag_pandas_demo.py', '--cfg-path', '/tmp/tmphia79kcl']
[2022-11-27T12:41:23.712+0000] {standard_task_runner.py:83} INFO - Job 351: Subtask creatableLoad
[2022-11-27T12:41:23.792+0000] {task_command.py:376} INFO - Running <TaskInstance: using_pandas_demo.creatableLoad manual__2022-11-27T12:41:11.917012+00:00 [running]> on host 1977dd9b5152
[2022-11-27T12:41:23.872+0000] {taskinstance.py:1592} INFO - Exporting the following env vars:
AIRFLOW_CTX_DAG_OWNER=***
AIRFLOW_CTX_DAG_ID=using_pandas_demo
AIRFLOW_CTX_TASK_ID=creatableLoad
AIRFLOW_CTX_EXECUTION_DATE=2022-11-27T12:41:11.917012+00:00
AIRFLOW_CTX_TRY_NUMBER=1
AIRFLOW_CTX_DAG_RUN_ID=manual__2022-11-27T12:41:11.917012+00:00
[2022-11-27T12:41:23.874+0000] {logging_mixin.py:137} INFO - connection to server at "0.0.0.0", port 5432 failed: Connection refused
	Is the server running on that host and accepting TCP/IP connections?
[2022-11-27T12:41:23.874+0000] {taskinstance.py:1851} ERROR - Task failed with exception
Traceback (most recent call last):
  File "/home/airflow/.local/lib/python3.7/site-packages/airflow/operators/python.py", line 175, in execute
    return_value = self.execute_callable()
  File "/home/airflow/.local/lib/python3.7/site-packages/airflow/operators/python.py", line 193, in execute_callable
    return self.python_callable(*self.op_args, **self.op_kwargs)
  File "/opt/airflow/dags/dag_pandas_demo.py", line 49, in creatableLoad
    cursor = dbconnect.cursor()
UnboundLocalError: local variable 'dbconnect' referenced before assignment
[2022-11-27T12:41:23.885+0000] {taskinstance.py:1406} INFO - Marking task as UP_FOR_RETRY. dag_id=using_pandas_demo, task_id=creatableLoad, execution_date=20221127T124111, start_date=20221127T124123, end_date=20221127T124123
[2022-11-27T12:41:23.899+0000] {standard_task_runner.py:105} ERROR - Failed to execute job 351 for task creatableLoad (local variable 'dbconnect' referenced before assignment; 1207)
[2022-11-27T12:41:23.921+0000] {local_task_job.py:159} INFO - Task exited with return code 1
[2022-11-27T12:41:23.942+0000] {taskinstance.py:2623} INFO - 0 downstream tasks scheduled from follow-on schedule check
