[2022-11-27T16:30:23.944+0000] {taskinstance.py:1165} INFO - Dependencies all met for <TaskInstance: dag_youtube_api.creatableLoad manual__2022-11-27T16:30:21.192007+00:00 [queued]>
[2022-11-27T16:30:23.991+0000] {taskinstance.py:1165} INFO - Dependencies all met for <TaskInstance: dag_youtube_api.creatableLoad manual__2022-11-27T16:30:21.192007+00:00 [queued]>
[2022-11-27T16:30:23.991+0000] {taskinstance.py:1362} INFO - 
--------------------------------------------------------------------------------
[2022-11-27T16:30:23.992+0000] {taskinstance.py:1363} INFO - Starting attempt 1 of 2
[2022-11-27T16:30:23.992+0000] {taskinstance.py:1364} INFO - 
--------------------------------------------------------------------------------
[2022-11-27T16:30:24.060+0000] {taskinstance.py:1383} INFO - Executing <Task(PythonOperator): creatableLoad> on 2022-11-27 16:30:21.192007+00:00
[2022-11-27T16:30:24.078+0000] {standard_task_runner.py:55} INFO - Started process 9803 to run task
[2022-11-27T16:30:24.104+0000] {standard_task_runner.py:82} INFO - Running: ['***', 'tasks', 'run', 'dag_youtube_api', 'creatableLoad', 'manual__2022-11-27T16:30:21.192007+00:00', '--job-id', '376', '--raw', '--subdir', 'DAGS_FOLDER/dag_youtube_api.py', '--cfg-path', '/tmp/tmp3og9drch']
[2022-11-27T16:30:24.109+0000] {standard_task_runner.py:83} INFO - Job 376: Subtask creatableLoad
[2022-11-27T16:30:24.356+0000] {task_command.py:376} INFO - Running <TaskInstance: dag_youtube_api.creatableLoad manual__2022-11-27T16:30:21.192007+00:00 [running]> on host 1977dd9b5152
[2022-11-27T16:30:24.627+0000] {taskinstance.py:1592} INFO - Exporting the following env vars:
AIRFLOW_CTX_DAG_OWNER=***
AIRFLOW_CTX_DAG_ID=dag_youtube_api
AIRFLOW_CTX_TASK_ID=creatableLoad
AIRFLOW_CTX_EXECUTION_DATE=2022-11-27T16:30:21.192007+00:00
AIRFLOW_CTX_TRY_NUMBER=1
AIRFLOW_CTX_DAG_RUN_ID=manual__2022-11-27T16:30:21.192007+00:00
[2022-11-27T16:30:24.690+0000] {taskinstance.py:1851} ERROR - Task failed with exception
Traceback (most recent call last):
  File "/home/airflow/.local/lib/python3.7/site-packages/airflow/operators/python.py", line 175, in execute
    return_value = self.execute_callable()
  File "/home/airflow/.local/lib/python3.7/site-packages/airflow/operators/python.py", line 193, in execute_callable
    return self.python_callable(*self.op_args, **self.op_kwargs)
  File "/opt/airflow/dags/dag_youtube_api.py", line 154, in creatableLoad
    with open('/opt/airflow/data/' + str('ID')  + '.csv', 'r') as f:
FileNotFoundError: [Errno 2] No such file or directory: '/opt/airflow/data/ID.csv'
[2022-11-27T16:30:24.724+0000] {taskinstance.py:1406} INFO - Marking task as UP_FOR_RETRY. dag_id=dag_youtube_api, task_id=creatableLoad, execution_date=20221127T163021, start_date=20221127T163023, end_date=20221127T163024
[2022-11-27T16:30:24.768+0000] {standard_task_runner.py:105} ERROR - Failed to execute job 376 for task creatableLoad ([Errno 2] No such file or directory: '/opt/airflow/data/ID.csv'; 9803)
[2022-11-27T16:30:24.806+0000] {local_task_job.py:159} INFO - Task exited with return code 1
[2022-11-27T16:30:24.845+0000] {taskinstance.py:2623} INFO - 0 downstream tasks scheduled from follow-on schedule check
