[2022-11-27T16:36:40.600+0000] {taskinstance.py:1165} INFO - Dependencies all met for <TaskInstance: dag_youtube_api.creatableLoad manual__2022-11-27T16:31:31.130368+00:00 [queued]>
[2022-11-27T16:36:40.659+0000] {taskinstance.py:1165} INFO - Dependencies all met for <TaskInstance: dag_youtube_api.creatableLoad manual__2022-11-27T16:31:31.130368+00:00 [queued]>
[2022-11-27T16:36:40.659+0000] {taskinstance.py:1362} INFO - 
--------------------------------------------------------------------------------
[2022-11-27T16:36:40.660+0000] {taskinstance.py:1363} INFO - Starting attempt 2 of 2
[2022-11-27T16:36:40.660+0000] {taskinstance.py:1364} INFO - 
--------------------------------------------------------------------------------
[2022-11-27T16:36:40.745+0000] {taskinstance.py:1383} INFO - Executing <Task(PythonOperator): creatableLoad> on 2022-11-27 16:31:31.130368+00:00
[2022-11-27T16:36:40.762+0000] {standard_task_runner.py:55} INFO - Started process 10051 to run task
[2022-11-27T16:36:40.798+0000] {standard_task_runner.py:82} INFO - Running: ['***', 'tasks', 'run', 'dag_youtube_api', 'creatableLoad', 'manual__2022-11-27T16:31:31.130368+00:00', '--job-id', '388', '--raw', '--subdir', 'DAGS_FOLDER/dag_youtube_api.py', '--cfg-path', '/tmp/tmp9iwnbgsn']
[2022-11-27T16:36:40.816+0000] {standard_task_runner.py:83} INFO - Job 388: Subtask creatableLoad
[2022-11-27T16:36:41.061+0000] {task_command.py:376} INFO - Running <TaskInstance: dag_youtube_api.creatableLoad manual__2022-11-27T16:31:31.130368+00:00 [running]> on host 1977dd9b5152
[2022-11-27T16:36:41.438+0000] {taskinstance.py:1592} INFO - Exporting the following env vars:
AIRFLOW_CTX_DAG_OWNER=***
AIRFLOW_CTX_DAG_ID=dag_youtube_api
AIRFLOW_CTX_TASK_ID=creatableLoad
AIRFLOW_CTX_EXECUTION_DATE=2022-11-27T16:31:31.130368+00:00
AIRFLOW_CTX_TRY_NUMBER=2
AIRFLOW_CTX_DAG_RUN_ID=manual__2022-11-27T16:31:31.130368+00:00
[2022-11-27T16:36:41.477+0000] {taskinstance.py:1851} ERROR - Task failed with exception
Traceback (most recent call last):
  File "/home/airflow/.local/lib/python3.7/site-packages/airflow/operators/python.py", line 175, in execute
    return_value = self.execute_callable()
  File "/home/airflow/.local/lib/python3.7/site-packages/airflow/operators/python.py", line 193, in execute_callable
    return self.python_callable(*self.op_args, **self.op_kwargs)
  File "/opt/airflow/dags/dag_youtube_api.py", line 170, in creatableLoad
    row.split(",")[10])
psycopg2.errors.StringDataRightTruncation: value too long for type character varying(50)

[2022-11-27T16:36:41.507+0000] {taskinstance.py:1406} INFO - Marking task as FAILED. dag_id=dag_youtube_api, task_id=creatableLoad, execution_date=20221127T163131, start_date=20221127T163640, end_date=20221127T163641
[2022-11-27T16:36:41.557+0000] {standard_task_runner.py:105} ERROR - Failed to execute job 388 for task creatableLoad (value too long for type character varying(50)
; 10051)
[2022-11-27T16:36:41.634+0000] {local_task_job.py:159} INFO - Task exited with return code 1
[2022-11-27T16:36:41.753+0000] {taskinstance.py:2623} INFO - 0 downstream tasks scheduled from follow-on schedule check
