[2022-11-28T16:29:50.992+0000] {taskinstance.py:1165} INFO - Dependencies all met for <TaskInstance: dag_try_oop.loadYtApiOperator scheduled__2022-11-28T03:30:00+00:00 [queued]>
[2022-11-28T16:29:51.350+0000] {taskinstance.py:1165} INFO - Dependencies all met for <TaskInstance: dag_try_oop.loadYtApiOperator scheduled__2022-11-28T03:30:00+00:00 [queued]>
[2022-11-28T16:29:51.362+0000] {taskinstance.py:1362} INFO - 
--------------------------------------------------------------------------------
[2022-11-28T16:29:51.374+0000] {taskinstance.py:1363} INFO - Starting attempt 1 of 2
[2022-11-28T16:29:51.386+0000] {taskinstance.py:1364} INFO - 
--------------------------------------------------------------------------------
[2022-11-28T16:29:52.054+0000] {taskinstance.py:1383} INFO - Executing <Task(loadYtApiOperator): loadYtApiOperator> on 2022-11-28 03:30:00+00:00
[2022-11-28T16:29:52.277+0000] {standard_task_runner.py:55} INFO - Started process 592 to run task
[2022-11-28T16:29:52.695+0000] {standard_task_runner.py:82} INFO - Running: ['***', 'tasks', 'run', 'dag_try_oop', 'loadYtApiOperator', 'scheduled__2022-11-28T03:30:00+00:00', '--job-id', '811', '--raw', '--subdir', 'DAGS_FOLDER/dag_try_oop.py', '--cfg-path', '/tmp/tmpnlm2fb_q']
[2022-11-28T16:29:52.745+0000] {standard_task_runner.py:83} INFO - Job 811: Subtask loadYtApiOperator
[2022-11-28T16:29:54.140+0000] {task_command.py:376} INFO - Running <TaskInstance: dag_try_oop.loadYtApiOperator scheduled__2022-11-28T03:30:00+00:00 [running]> on host 1dd759b3e30c
[2022-11-28T16:29:55.661+0000] {taskinstance.py:1592} INFO - Exporting the following env vars:
AIRFLOW_CTX_DAG_OWNER=***
AIRFLOW_CTX_DAG_ID=dag_try_oop
AIRFLOW_CTX_TASK_ID=loadYtApiOperator
AIRFLOW_CTX_EXECUTION_DATE=2022-11-28T03:30:00+00:00
AIRFLOW_CTX_TRY_NUMBER=1
AIRFLOW_CTX_DAG_RUN_ID=scheduled__2022-11-28T03:30:00+00:00
[2022-11-28T16:29:55.805+0000] {taskinstance.py:1851} ERROR - Task failed with exception
Traceback (most recent call last):
  File "/opt/airflow/plugins/operators/loadYtApiOperator.py", line 68, in execute
    row.split(",")[9],
IndexError: list index out of range
[2022-11-28T16:29:55.903+0000] {taskinstance.py:1406} INFO - Marking task as UP_FOR_RETRY. dag_id=dag_try_oop, task_id=loadYtApiOperator, execution_date=20221128T033000, start_date=20221128T162951, end_date=20221128T162955
[2022-11-28T16:29:56.441+0000] {standard_task_runner.py:105} ERROR - Failed to execute job 811 for task loadYtApiOperator (list index out of range; 592)
[2022-11-28T16:29:56.723+0000] {local_task_job.py:159} INFO - Task exited with return code 1
[2022-11-28T16:29:57.060+0000] {taskinstance.py:2623} INFO - 0 downstream tasks scheduled from follow-on schedule check
